File: Irregular grid FORC measurements/Fig. 8f Zebra rock red mpms FORC test.rso.dat
[Header]
TITLE,MPMS RSO Measurement
BYAPP,MPMS Measurement,1.1,Summary
FILEOPENTIME, 1545016886.057000 12/17/2018, 2:21:26 PM

INFO, APPNAME, MPMS MultiVu Application, Revision 1.60,  Build 081

INFO, NAME, Zebra Rock Red xiang
INFO, WEIGHT, 1.000
INFO, AREA, 1.000
INFO, LENGTH, 1.000
INFO, SHAPE,
INFO, COMMENT,
INFO, SEQUENCE FILE: Zebra Rock Red xiang LOOP_hys-osci-noover_ 5T_after LT refilled.rso.datMPMS FORC.seq


INFO, BACKGROUND DATA FILE:, None


STARTUPAXIS,X,4,LINEAR,AUTO,0.000000,0.000000
STARTUPAXIS,Y1,5,LINEAR,AUTO,0.000000,0.000000


STARTUPGROUP,Longitudinal
FIELDGROUP,Longitudinal,1,2,3,4,5,6,7,8,9,10,11,19,20,21,22,23,35
FIELDGROUP,Transverse,1,2,3,4,12,13,14,15,16,17,18,24,25,26,27,28,35

PLOT_APPEARANCE,ALL,HORZ_GRID_ON,VERT_GRID_ON,MARKERS_AND_LINES

[Data]
Time,Comment,Field (Oe),Temperature (K),Long Moment (emu),Long Scan Std Dev,Long Offset (cm),Long Offset Std Dev,Long Algorithm,Long Reg Fit,Long Reg Factor,Trans Moment (emu),Trans Scan Std Dev,Trans Offset (cm),Trans Offset Std Dev,Trans Algorithm,Trans Reg Fit,Trans Reg Factor,Long Moment [w/o ABS] (emu),Long Scan Std Dev [w/o ABS],Long Offset [w/o ABS] (cm),Long Offset Std Dev [w/o ABS],Long Reg Fit [w/o ABS],Trans Moment [w/o ABS] (emu),Trans Scan Std Dev [w/o ABS],Trans Offset [w/o ABS] (cm),Trans Offset Std Dev [w/o ABS],Trans Reg Fit [w/o ABS],RSO Position (deg),Amplitude (cm),Frequency,Cycles to Average,Scans per Measurement,Delta Temp (K),Error,EC Comp. Running,Using ABS,
1545016886.057,,4.244427e+004,2.999997e+002,1.459320e-002,0.000000e+000,1.047786e-003,0.000000e+000,3,9.730385e-001,1.825000e+000,,,,,,,,,,,,,,,,,,0,4.000000e+000,1.000000e+000,5,1,0.000000e+000,0,0,0,
1545018119.946,,2.338042e+004,2.999997e+002,9.594082e-003,0.000000e+000,3.016677e-003,0.000000e+000,3,9.718904e-001,1.825000e+000,,,,,,,,,,,,,,,,,,0,4.000000e+000,1.000000e+000,5,1,0.000000e+000,0,1,0,
1545019208.146,,1.377658e+004,2.999997e+002,6.989347e-003,0.000000e+000,4.826953e-003,0.000000e+000,3,9.709569e-001,1.825000e+000,,,,,,,,,,,,,,,,,,0,4.000000e+000,1.000000e+000,5,1,0.000000e+000,0,1,0,
1545020037.728,,1.500216e+004,2.999997e+002,7.326850e-003,0.000000e+000,5.311341e-003,0.000000e+000,3,9.710715e-001,1.825000e+000,,,,,,,,,,,,,,,,,,0,4.000000e+000,1.000000e+000,5,1,0.000000e+000,0,1,0,
1545020861.891,,1.050084e+004,2.999956e+002,6.065998e-003,0.000000e+000,6.452943e-003,0.000000e+000,3,9.702786e-001,1.825000e+000,,,,,,,,,,,,,,,,,,0,4.000000e+000,1.000000e+000,5,1,8.209229e-003,0,1,0,
1545021754.627,,6.279689e+003,2.999997e+002,4.816230e-003,0.000000e+000,7.591026e-003,0.000000e+000,3,9.695084e-001,1.825000e+000,,,,,,,,,,,,,,,,,,0,4.000000e+000,1.000000e+000,5,1,0.000000e+000,0,1,0,
1545022309.812,,2.056511e+004,2.999997e+002,8.833162e-003,0.000000e+000,5.262819e-003,0.000000e+000,3,9.717081e-001,1.825000e+000,,,,,,,,,,,,,,,,,,0,4.000000e+000,1.000000e+000,5,1,0.000000e+000,0,1,0,
1545023161.534,,6.057788e+003,3.000079e+002,4.744906e-003,0.000000e+000,8.229990e-003,0.000000e+000,3,9.693937e-001,1.825000e+000,,,,,,,,,,,,,,,,,,0,4.000000e+000,1.000000e+000,5,1,1.651001e-002,0,1,0,
1545023706.899,,1.830925e+004,2.999915e+002,8.221172e-003,0.000000e+000,5.965380e-003,0.000000e+000,3,9.715642e-001,1.825000e+000,,,,,,,,,,,,,,,,,,0,4.000000e+000,1.000000e+000,5,1,0.000000e+000,0,0,0,
1545024570.742,,4.470664e+003,3.000038e+002,4.238583e-003,0.000000e+000,8.710973e-003,0.000000e+000,3,9.689526e-001,1.825000e+000,,,,,,,,,,,,,,,,,,0,4.000000e+000,1.000000e+000,5,1,8.300781e-003,0,1,0,
1545025078.021,,9.435145e+003,2.999956e+002,5.750352e-003,0.000000e+000,8.015190e-003,0.000000e+000,3,9.702044e-001,1.825000e+000,,,,,,,,,,,,,,,,,,0,4.000000e+000,1.000000e+000,5,1,8.209229e-003,0,0,0,
1545025990.967,,2.317514e+003,2.999997e+002,3.500671e-003,0.000000e+000,9.557609e-003,0.000000e+000,3,9.681803e-001,1.825000e+000,,,,,,,,,,,,,,,,,,0,4.000000e+000,1.000000e+000,5,1,0.000000e+000,0,1,0,
1545026450.963,,5.294801e+003,2.999997e+002,4.497879e-003,0.000000e+000,9.083997e-003,0.000000e+000,3,9.692533e-001,1.825000e+000,,,,,,,,,,,,,,,,,,0,4.000000e+000,1.000000e+000,5,1,0.000000e+000,0,1,0,
1545026969.506,,1.275395e+004,2.999956e+002,6.688485e-003,0.000000e+000,7.470381e-003,0.000000e+000,3,9.709418e-001,1.825000e+000,,,,,,,,,,,,,,,,,,0,4.000000e+000,1.000000e+000,5,1,8.209229e-003,0,0,0,
1545027886.950,,2.614513e+003,2.999997e+002,3.597481e-003,0.000000e+000,9.944512e-003,0.000000e+000,3,9.682423e-001,1.825000e+000,,,,,,,,,,,,,,,,,,0,4.000000e+000,1.000000e+000,5,1,0.000000e+000,0,1,0,
1545028349.636,,5.662128e+003,2.999997e+002,4.609622e-003,0.000000e+000,9.379039e-003,0.000000e+000,3,9.693273e-001,1.825000e+000,,,,,,,,,,,,,,,,,,0,4.000000e+000,1.000000e+000,5,1,0.000000e+000,0,0,0,
1545028879.917,,1.500100e+004,2.999915e+002,7.305396e-003,0.000000e+000,7.360685e-003,0.000000e+000,3,9.712930e-001,1.825000e+000,,,,,,,,,,,,,,,,,,0,4.000000e+000,1.000000e+000,5,1,0.000000e+000,0,1,0,
1545029790.932,,2.470026e+003,2.999997e+002,3.539941e-003,0.000000e+000,1.031556e-002,0.000000e+000,3,9.682204e-001,1.825000e+000,,,,,,,,,,,,,,,,,,0,4.000000e+000,1.000000e+000,5,1,0.000000e+000,0,1,0,
1545030252.447,,5.472465e+003,2.999956e+002,4.546147e-003,0.000000e+000,9.589145e-003,0.000000e+000,3,9.693893e-001,1.825000e+000,,,,,,,,,,,,,,,,,,0,4.000000e+000,1.000000e+000,5,1,8.209229e-003,0,0,0,
1545030773.464,,1.377570e+004,3.000038e+002,6.962994e-003,0.000000e+000,8.022853e-003,0.000000e+000,3,9.711896e-001,1.825000e+000,,,,,,,,,,,,,,,,,,0,4.000000e+000,1.000000e+000,5,1,8.300781e-003,0,1,0,
1545031702.460,,2.165003e+003,2.999998e+002,3.419828e-003,0.000000e+000,1.080175e-002,0.000000e+000,3,9.681208e-001,1.825000e+000,,,,,,,,,,,,,,,,,,0,4.000000e+000,1.000000e+000,5,1,1.651001e-002,0,0,0,
1545032168.806,,5.118293e+003,2.999998e+002,4.431569e-003,0.000000e+000,9.953273e-003,0.000000e+000,3,9.691601e-001,1.825000e+000,,,,,,,,,,,,,,,,,,0,4.000000e+000,1.000000e+000,5,1,1.651001e-002,0,1,0,
1545032686.684,,1.188948e+004,2.999997e+002,6.432206e-003,0.000000e+000,8.667956e-003,0.000000e+000,3,9.710552e-001,1.825000e+000,,,,,,,,,,,,,,,,,,0,4.000000e+000,1.000000e+000,5,1,0.000000e+000,0,1,0,
1545033578.463,,1.492294e+003,2.999997e+002,3.148642e-003,0.000000e+000,1.121613e-002,0.000000e+000,3,9.677753e-001,1.825000e+000,,,,,,,,,,,,,,,,,,0,4.000000e+000,1.000000e+000,5,1,0.000000e+000,0,0,0,
1545034038.700,,4.470520e+003,3.000038e+002,4.215730e-003,0.000000e+000,1.044719e-002,0.000000e+000,3,9.690750e-001,1.825000e+000,,,,,,,,,,,,,,,,,,0,4.000000e+000,1.000000e+000,5,1,8.300781e-003,0,1,0,
1545034549.389,,9.434278e+003,3.000038e+002,5.731489e-003,0.000000e+000,9.437051e-003,0.000000e+000,3,9.705628e-001,1.825000e+000,,,,,,,,,,,,,,,,,,0,4.000000e+000,1.000000e+000,5,1,8.300781e-003,0,1,0,
1545035451.228,,6.031479e+002,2.999997e+002,2.750944e-003,0.000000e+000,1.174752e-002,0.000000e+000,3,9.673427e-001,1.825000e+000,,,,,,,,,,,,,,,,,,0,4.000000e+000,1.000000e+000,5,1,0.000000e+000,0,1,0,
1545035909.113,,3.880354e+003,2.999997e+002,4.018533e-003,0.000000e+000,1.082071e-002,0.000000e+000,3,9.688114e-001,1.825000e+000,,,,,,,,,,,,,,,,,,0,4.000000e+000,1.000000e+000,5,1,0.000000e+000,0,1,0,
1545036418.830,,7.873608e+003,2.999956e+002,5.274413e-003,0.000000e+000,9.914133e-003,0.000000e+000,3,9.701167e-001,1.825000e+000,,,,,,,,,,,,,,,,,,0,4.000000e+000,1.000000e+000,5,1,8.209229e-003,0,0,0,
1545037064.435,,5.038063e+004,3.000038e+002,1.652662e-002,0.000000e+000,5.756516e-003,0.000000e+000,3,9.739105e-001,1.825000e+000,,,,,,,,,,,,,,,,,,0,4.000000e+000,1.000000e+000,5,1,8.300781e-003,0,1,0,
1545037789.514,,3.178731e+003,2.999956e+002,3.770465e-003,0.000000e+000,1.117984e-002,0.000000e+000,3,9.685819e-001,1.825000e+000,,,,,,,,,,,,,,,,,,0,4.000000e+000,1.000000e+000,5,1,8.209229e-003,0,0,0,
1545038265.989,,6.501443e+003,2.999956e+002,4.858645e-003,0.000000e+000,1.001551e-002,0.000000e+000,3,9.697714e-001,1.825000e+000,,,,,,,,,,,,,,,,,,0,4.000000e+000,1.000000e+000,5,1,8.209229e-003,0,0,0,
1545038839.350,,2.337970e+004,2.999997e+002,9.538440e-003,0.000000e+000,7.530501e-003,0.000000e+000,3,9.725149e-001,1.825000e+000,,,,,,,,,,,,,,,,,,0,4.000000e+000,1.000000e+000,5,1,0.000000e+000,0,1,0,
1545039686.270,,2.317514e+003,2.999956e+002,3.448161e-003,0.000000e+000,1.138309e-002,0.000000e+000,3,9.681531e-001,1.825000e+000,,,,,,,,,,,,,,,,,,0,4.000000e+000,1.000000e+000,5,1,8.209229e-003,0,0,0,
1545040149.747,,5.294945e+003,2.999997e+002,4.476974e-003,0.000000e+000,1.077516e-002,0.000000e+000,3,9.692590e-001,1.825000e+000,,,,,,,,,,,,,,,,,,0,4.000000e+000,1.000000e+000,5,1,0.000000e+000,0,1,0,
1545040669.633,,1.275453e+004,3.000038e+002,6.674093e-003,0.000000e+000,9.142878e-003,0.000000e+000,3,9.710573e-001,1.825000e+000,,,,,,,,,,,,,,,,,,0,4.000000e+000,1.000000e+000,5,1,8.300781e-003,0,1,0,
1545041561.655,,1.288695e+003,2.999915e+002,3.013173e-003,0.000000e+000,1.179896e-002,0.000000e+000,3,9.676972e-001,1.825000e+000,,,,,,,,,,,,,,,,,,0,4.000000e+000,1.000000e+000,5,1,0.000000e+000,0,1,0,
1545042025.845,,4.321045e+003,2.999997e+002,4.158619e-003,0.000000e+000,1.089411e-002,0.000000e+000,3,9.690356e-001,1.825000e+000,,,,,,,,,,,,,,,,,,0,4.000000e+000,1.000000e+000,5,1,0.000000e+000,0,1,0,
1545042546.873,,8.984696e+003,2.999956e+002,5.601576e-003,0.000000e+000,9.734839e-003,0.000000e+000,3,9.703074e-001,1.825000e+000,,,,,,,,,,,,,,,,,,0,4.000000e+000,1.000000e+000,5,1,8.209229e-003,0,0,0,
1545043461.918,,-3.811615e+002,2.999997e+002,2.048570e-003,0.000000e+000,1.378123e-002,0.000000e+000,3,9.670262e-001,1.825000e+000,,,,,,,,,,,,,,,,,,0,4.000000e+000,1.000000e+000,5,1,0.000000e+000,0,1,0,
1545043929.614,,3.456720e+003,2.999997e+002,3.857162e-003,0.000000e+000,1.108641e-002,0.000000e+000,3,9.686296e-001,1.825000e+000,,,,,,,,,,,,,,,,,,0,4.000000e+000,1.000000e+000,5,1,0.000000e+000,0,0,0,
1545044450.966,,6.995983e+003,2.999997e+002,5.007870e-003,0.000000e+000,1.023112e-002,0.000000e+000,3,9.698634e-001,1.825000e+000,,,,,,,,,,,,,,,,,,0,4.000000e+000,1.000000e+000,5,1,0.000000e+000,0,1,0,
1545045017.066,,3.127123e+004,2.999997e+002,1.161009e-002,0.000000e+000,6.912354e-003,0.000000e+000,3,9.730656e-001,1.825000e+000,,,,,,,,,,,,,,,,,,0,4.000000e+000,1.000000e+000,5,1,0.000000e+000,0,1,0,
1545045841.006,,2.470026e+003,2.999998e+002,3.482540e-003,0.000000e+000,1.139292e-002,0.000000e+000,3,9.680563e-001,1.825000e+000,,,,,,,,,,,,,,,,,,0,4.000000e+000,1.000000e+000,5,1,1.651001e-002,0,1,0,
1545046312.242,,5.472465e+003,2.999956e+002,4.531276e-003,0.000000e+000,1.084152e-002,0.000000e+000,3,9.692602e-001,1.825000e+000,,,,,,,,,,,,,,,,,,0,4.000000e+000,1.000000e+000,5,1,8.209229e-003,0,1,0,
1545046838.983,,1.377570e+004,2.999956e+002,6.957564e-003,0.000000e+000,8.929359e-003,0.000000e+000,3,9.712606e-001,1.825000e+000,,,,,,,,,,,,,,,,,,0,4.000000e+000,1.000000e+000,5,1,8.209229e-003,0,0,0,
1545047738.015,,1.288753e+003,2.999997e+002,2.911231e-003,0.000000e+000,1.259346e-002,0.000000e+000,3,9.674255e-001,1.825000e+000,,,,,,,,,,,,,,,,,,0,4.000000e+000,1.000000e+000,5,1,0.000000e+000,0,1,0,
1545048187.570,,4.321188e+003,2.999915e+002,4.151101e-003,0.000000e+000,1.118004e-002,0.000000e+000,3,9.689748e-001,1.825000e+000,,,,,,,,,,,,,,,,,,0,4.000000e+000,1.000000e+000,5,1,0.000000e+000,0,0,0,
1545048714.432,,8.984118e+003,2.999997e+002,5.601862e-003,0.000000e+000,9.866291e-003,0.000000e+000,3,9.703193e-001,1.825000e+000,,,,,,,,,,,,,,,,,,0,4.000000e+000,1.000000e+000,5,1,0.000000e+000,0,1,0,
1545049620.604,,-8.268689e+002,2.999997e+002,1.622236e-003,0.000000e+000,1.635830e-002,0.000000e+000,3,9.665936e-001,1.825000e+000,,,,,,,,,,,,,,,,,,0,4.000000e+000,1.000000e+000,5,1,0.000000e+000,0,1,0,
1545050100.032,,3.318158e+003,2.999997e+002,3.790451e-003,0.000000e+000,1.159050e-002,0.000000e+000,3,9.683214e-001,1.825000e+000,,,,,,,,,,,,,,,,,,0,4.000000e+000,1.000000e+000,5,1,0.000000e+000,0,0,0,
1545050568.638,,6.745460e+003,3.000038e+002,4.928531e-003,0.000000e+000,1.050557e-002,0.000000e+000,3,9.698045e-001,1.825000e+000,,,,,,,,,,,,,,,,,,0,4.000000e+000,1.000000e+000,5,1,8.300781e-003,0,1,0,
1545051155.923,,2.690480e+004,2.999915e+002,1.047362e-002,0.000000e+000,7.466248e-003,0.000000e+000,3,9.727093e-001,1.825000e+000,,,,,,,,,,,,,,,,,,0,4.000000e+000,1.000000e+000,5,1,0.000000e+000,0,0,0,
1545052003.973,,2.165003e+003,3.000038e+002,3.313501e-003,0.000000e+000,1.184447e-002,0.000000e+000,3,9.679445e-001,1.825000e+000,,,,,,,,,,,,,,,,,,0,4.000000e+000,1.000000e+000,5,1,8.300781e-003,0,1,0,
1545052468.402,,5.118437e+003,2.999997e+002,4.406787e-003,0.000000e+000,1.101271e-002,0.000000e+000,3,9.693528e-001,1.825000e+000,,,,,,,,,,,,,,,,,,0,4.000000e+000,1.000000e+000,5,1,0.000000e+000,0,1,0,
1545052986.192,,1.188948e+004,2.999915e+002,6.431917e-003,0.000000e+000,9.429813e-003,0.000000e+000,3,9.710026e-001,1.825000e+000,,,,,,,,,,,,,,,,,,0,4.000000e+000,1.000000e+000,5,1,0.000000e+000,0,0,0,
1545053896.875,,6.031190e+002,2.999956e+002,2.303356e-003,0.000000e+000,1.553697e-002,0.000000e+000,3,9.674046e-001,1.825000e+000,,,,,,,,,,,,,,,,,,0,4.000000e+000,1.000000e+000,5,1,8.209229e-003,0,1,0,
1545054370.203,,3.880354e+003,3.000038e+002,3.980201e-003,0.000000e+000,1.150655e-002,0.000000e+000,3,9.687415e-001,1.825000e+000,,,,,,,,,,,,,,,,,,0,4.000000e+000,1.000000e+000,5,1,8.300781e-003,0,0,0,
1545054884.373,,7.873174e+003,2.999997e+002,5.268124e-003,0.000000e+000,1.030665e-002,0.000000e+000,3,9.700429e-001,1.825000e+000,,,,,,,,,,,,,,,,,,0,4.000000e+000,1.000000e+000,5,1,0.000000e+000,0,1,0,
1545055533.810,,5.038352e+004,3.000038e+002,1.655485e-002,0.000000e+000,6.328945e-003,0.000000e+000,3,9.737539e-001,1.825000e+000,,,,,,,,,,,,,,,,,,0,4.000000e+000,1.000000e+000,5,1,8.300781e-003,0,1,0,
1545056295.327,,2.757122e+003,2.999997e+002,3.533535e-003,0.000000e+000,1.147422e-002,0.000000e+000,3,9.684633e-001,1.825000e+000,,,,,,,,,,,,,,,,,,0,4.000000e+000,1.000000e+000,5,1,0.000000e+000,0,1,0,
1545056755.382,,5.859019e+003,2.999997e+002,4.642845e-003,0.000000e+000,1.091424e-002,0.000000e+000,3,9.694093e-001,1.825000e+000,,,,,,,,,,,,,,,,,,0,4.000000e+000,1.000000e+000,5,1,0.000000e+000,0,1,0,
1545057290.915,,1.648852e+004,2.999956e+002,7.702284e-003,0.000000e+000,8.754628e-003,0.000000e+000,3,9.715912e-001,1.825000e+000,,,,,,,,,,,,,,,,,,0,4.000000e+000,1.000000e+000,5,1,8.209229e-003,0,0,0,
1545058197.771,,1.492322e+003,3.000038e+002,2.757193e-003,0.000000e+000,1.368455e-002,0.000000e+000,3,9.676141e-001,1.825000e+000,,,,,,,,,,,,,,,,,,0,4.000000e+000,1.000000e+000,5,1,8.300781e-003,0,1,0,
1545058655.589,,4.470664e+003,2.999997e+002,4.175039e-003,0.000000e+000,1.150149e-002,0.000000e+000,3,9.688815e-001,1.825000e+000,,,,,,,,,,,,,,,,,,0,4.000000e+000,1.000000e+000,5,1,0.000000e+000,0,0,0,
1545059175.829,,9.434856e+003,2.999956e+002,5.730829e-003,0.000000e+000,1.006729e-002,0.000000e+000,3,9.702212e-001,1.825000e+000,,,,,,,,,,,,,,,,,,0,4.000000e+000,1.000000e+000,5,1,8.209229e-003,0,1,0,
1545060087.187,,-8.268256e+002,2.999956e+002,1.230740e-003,0.000000e+000,2.019302e-002,0.000000e+000,3,9.663678e-001,1.825000e+000,,,,,,,,,,,,,,,,,,0,4.000000e+000,1.000000e+000,5,1,8.209229e-003,0,0,0,
1545060554.946,,3.318231e+003,2.999956e+002,3.735176e-003,0.000000e+000,1.170087e-002,0.000000e+000,3,9.684823e-001,1.825000e+000,,,,,,,,,,,,,,,,,,0,4.000000e+000,1.000000e+000,5,1,8.209229e-003,0,0,0,
1545061024.374,,6.745605e+003,2.999997e+002,4.917548e-003,0.000000e+000,1.100329e-002,0.000000e+000,3,9.695210e-001,1.825000e+000,,,,,,,,,,,,,,,,,,0,4.000000e+000,1.000000e+000,5,1,0.000000e+000,0,1,0,
1545061616.386,,2.690551e+004,2.999997e+002,1.047883e-002,0.000000e+000,7.659625e-003,0.000000e+000,3,9.726740e-001,1.825000e+000,,,,,,,,,,,,,,,,,,0,4.000000e+000,1.000000e+000,5,1,0.000000e+000,0,0,0,
1545062478.918,,2.165075e+003,2.999997e+002,3.091768e-003,0.000000e+000,1.246375e-002,0.000000e+000,3,9.679001e-001,1.825000e+000,,,,,,,,,,,,,,,,,,0,4.000000e+000,1.000000e+000,5,1,0.000000e+000,0,1,0,
1545062941.215,,5.118437e+003,2.999997e+002,4.383734e-003,0.000000e+000,1.108845e-002,0.000000e+000,3,9.693232e-001,1.825000e+000,,,,,,,,,,,,,,,,,,0,4.000000e+000,1.000000e+000,5,1,0.000000e+000,0,1,0,
1545063452.336,,1.188978e+004,2.999956e+002,6.431101e-003,0.000000e+000,9.654948e-003,0.000000e+000,3,9.707859e-001,1.825000e+000,,,,,,,,,,,,,,,,,,0,4.000000e+000,1.000000e+000,5,1,8.209229e-003,0,0,0,
1545064371.041,,3.159938e+002,2.999997e+002,1.730959e-003,0.000000e+000,1.803260e-002,0.000000e+000,3,9.671739e-001,1.825000e+000,,,,,,,,,,,,,,,,,,0,4.000000e+000,1.000000e+000,5,1,0.000000e+000,0,1,0,
1545064839.459,,3.738757e+003,2.999956e+002,3.872724e-003,0.000000e+000,1.167394e-002,0.000000e+000,3,9.687202e-001,1.825000e+000,,,,,,,,,,,,,,,,,,0,4.000000e+000,1.000000e+000,5,1,8.209229e-003,0,0,0,
1545065352.951,,7.554853e+003,2.999956e+002,5.160375e-003,0.000000e+000,1.059960e-002,0.000000e+000,3,9.699461e-001,1.825000e+000,,,,,,,,,,,,,,,,,,0,4.000000e+000,1.000000e+000,5,1,8.209229e-003,0,1,0,
1545065962.546,,4.289531e+004,2.999997e+002,1.463887e-002,0.000000e+000,6.892652e-003,0.000000e+000,3,9.734166e-001,1.825000e+000,,,,,,,,,,,,,,,,,,0,4.000000e+000,1.000000e+000,5,1,0.000000e+000,0,0,0,
1545066778.367,,2.470170e+003,3.000038e+002,3.177846e-003,0.000000e+000,1.238703e-002,0.000000e+000,3,9.682513e-001,1.825000e+000,,,,,,,,,,,,,,,,,,0,4.000000e+000,1.000000e+000,5,1,8.300781e-003,0,1,0,
1545067246.774,,5.472754e+003,2.999997e+002,4.489377e-003,0.000000e+000,1.113767e-002,0.000000e+000,3,9.694573e-001,1.825000e+000,,,,,,,,,,,,,,,,,,0,4.000000e+000,1.000000e+000,5,1,0.000000e+000,0,1,0,
1545067778.876,,1.377570e+004,2.999956e+002,6.957439e-003,0.000000e+000,9.518698e-003,0.000000e+000,3,9.710966e-001,1.825000e+000,,,,,,,,,,,,,,,,,,0,4.000000e+000,1.000000e+000,5,1,8.209229e-003,0,0,0,
1545068679.670,,8.529476e+002,2.999997e+002,1.927833e-003,0.000000e+000,1.678002e-002,0.000000e+000,3,9.671464e-001,1.825000e+000,,,,,,,,,,,,,,,,,,0,4.000000e+000,1.000000e+000,5,1,0.000000e+000,0,1,0,
1545069145.068,,4.023033e+003,2.999956e+002,3.956427e-003,0.000000e+000,1.167614e-002,0.000000e+000,3,9.689804e-001,1.825000e+000,,,,,,,,,,,,,,,,,,0,4.000000e+000,1.000000e+000,5,1,8.209229e-003,0,0,0,
1545069672.959,,8.211445e+003,3.000038e+002,5.356146e-003,0.000000e+000,1.087257e-002,0.000000e+000,3,9.698377e-001,1.825000e+000,,,,,,,,,,,,,,,,,,0,4.000000e+000,1.000000e+000,5,1,8.300781e-003,0,1,0,
1545070588.011,,-3.318231e+003,2.999956e+002,-2.983871e-004,0.000000e+000,-3.315195e-002,0.000000e+000,3,9.845650e-001,1.825000e+000,,,,,,,,,,,,,,,,,,0,4.000000e+000,1.000000e+000,5,1,8.209229e-003,0,0,0,
1545071101.551,,2.757122e+003,2.999956e+002,3.259848e-003,0.000000e+000,1.219984e-002,0.000000e+000,3,9.681641e-001,1.825000e+000,,,,,,,,,,,,,,,,,,0,4.000000e+000,1.000000e+000,5,1,8.209229e-003,0,1,0,
1545071571.290,,5.859164e+003,2.999997e+002,4.607038e-003,0.000000e+000,1.124797e-002,0.000000e+000,3,9.694603e-001,1.825000e+000,,,,,,,,,,,,,,,,,,0,4.000000e+000,1.000000e+000,5,1,0.000000e+000,0,1,0,
1545072098.492,,1.648910e+004,2.999956e+002,7.702006e-003,0.000000e+000,9.287682e-003,0.000000e+000,3,9.715447e-001,1.825000e+000,,,,,,,,,,,,,,,,,,0,4.000000e+000,1.000000e+000,5,1,8.209229e-003,0,0,0,
1545073028.086,,1.288753e+003,2.999997e+002,2.076286e-003,0.000000e+000,1.577545e-002,0.000000e+000,3,9.673967e-001,1.825000e+000,,,,,,,,,,,,,,,,,,0,4.000000e+000,1.000000e+000,5,1,0.000000e+000,0,1,0,
1545073498.164,,4.321333e+003,2.999915e+002,4.045242e-003,0.000000e+000,1.156939e-002,0.000000e+000,3,9.689558e-001,1.825000e+000,,,,,,,,,,,,,,,,,,0,4.000000e+000,1.000000e+000,5,1,0.000000e+000,0,0,0,
1545074015.166,,8.984696e+003,2.999956e+002,5.581685e-003,0.000000e+000,1.060328e-002,0.000000e+000,3,9.702240e-001,1.825000e+000,,,,,,,,,,,,,,,,,,0,4.000000e+000,1.000000e+000,5,1,8.209229e-003,0,1,0,
1545074961.711,,-1.991314e+003,2.999997e+002,7.530444e-005,0.000000e+000,1.857033e-001,0.000000e+000,3,9.380832e-001,1.825000e+000,,,,,,,,,,,,,,,,,,0,4.000000e+000,1.000000e+000,5,1,0.000000e+000,0,0,0,
1545075449.831,,3.040243e+003,2.999997e+002,3.333835e-003,0.000000e+000,1.200266e-002,0.000000e+000,3,9.684199e-001,1.825000e+000,,,,,,,,,,,,,,,,,,0,4.000000e+000,1.000000e+000,5,1,0.000000e+000,0,1,0,
1545075912.049,,6.279833e+003,2.999997e+002,4.735599e-003,0.000000e+000,1.152460e-002,0.000000e+000,3,9.692693e-001,1.825000e+000,,,,,,,,,,,,,,,,,,0,4.000000e+000,1.000000e+000,5,1,0.000000e+000,0,1,0,
1545076473.601,,2.056584e+004,2.999997e+002,8.802006e-003,0.000000e+000,8.744083e-003,0.000000e+000,3,9.720188e-001,1.825000e+000,,,,,,,,,,,,,,,,,,0,4.000000e+000,1.000000e+000,5,1,0.000000e+000,0,0,0,
1545077389.614,,1.668107e+003,2.999997e+002,2.195141e-003,0.000000e+000,1.474977e-002,0.000000e+000,3,9.677580e-001,1.825000e+000,,,,,,,,,,,,,,,,,,0,4.000000e+000,1.000000e+000,5,1,0.000000e+000,0,1,0,
1545077844.641,,4.626500e+003,2.999997e+002,4.134998e-003,0.000000e+000,1.139808e-002,0.000000e+000,3,9.688219e-001,1.825000e+000,,,,,,,,,,,,,,,,,,0,4.000000e+000,1.000000e+000,5,1,0.000000e+000,0,0,0,
1545078360.082,,9.936479e+003,2.999956e+002,5.857534e-003,0.000000e+000,1.030981e-002,0.000000e+000,3,9.705381e-001,1.825000e+000,,,,,,,,,,,,,,,,,,0,4.000000e+000,1.000000e+000,5,1,8.209229e-003,0,1,0,
1545079294.310,,-8.268256e+002,2.999997e+002,4.290521e-004,0.000000e+000,3.704887e-002,0.000000e+000,3,9.651526e-001,1.825000e+000,,,,,,,,,,,,,,,,,,0,4.000000e+000,1.000000e+000,5,1,0.000000e+000,0,0,0,
1545079766.606,,3.318231e+003,2.999956e+002,3.408318e-003,0.000000e+000,1.168090e-002,0.000000e+000,3,9.686379e-001,1.825000e+000,,,,,,,,,,,,,,,,,,0,4.000000e+000,1.000000e+000,5,1,8.209229e-003,0,1,0,
1545080234.276,,6.745605e+003,3.000080e+002,4.875066e-003,0.000000e+000,1.104621e-002,0.000000e+000,3,9.695759e-001,1.825000e+000,,,,,,,,,,,,,,,,,,0,4.000000e+000,1.000000e+000,5,1,0.000000e+000,0,1,0,
1545080832.690,,2.690551e+004,2.999956e+002,1.048401e-002,0.000000e+000,8.058920e-003,0.000000e+000,3,9.724779e-001,1.825000e+000,,,,,,,,,,,,,,,,,,0,4.000000e+000,1.000000e+000,5,1,8.209229e-003,0,0,0,
1545081697.390,,1.839743e+003,2.999956e+002,2.157060e-003,0.000000e+000,1.389796e-002,0.000000e+000,3,9.681164e-001,1.825000e+000,,,,,,,,,,,,,,,,,,0,4.000000e+000,1.000000e+000,5,1,8.209229e-003,0,1,0,
1545082158.137,,4.787973e+003,2.999998e+002,4.168160e-003,0.000000e+000,1.182561e-002,0.000000e+000,3,9.689330e-001,1.825000e+000,,,,,,,,,,,,,,,,,,0,4.000000e+000,1.000000e+000,5,1,1.651001e-002,0,0,0,
1545082685.797,,1.049998e+004,2.999997e+002,6.017060e-003,0.000000e+000,1.018896e-002,0.000000e+000,3,9.705045e-001,1.825000e+000,,,,,,,,,,,,,,,,,,0,4.000000e+000,1.000000e+000,5,1,0.000000e+000,0,1,0,
1545083624.123,,-8.267822e+002,2.999956e+002,2.399545e-004,0.000000e+000,5.484466e-002,0.000000e+000,3,9.630729e-001,1.825000e+000,,,,,,,,,,,,,,,,,,0,4.000000e+000,1.000000e+000,5,1,8.209229e-003,0,0,0,
1545084120.773,,3.318231e+003,2.999998e+002,3.279034e-003,0.000000e+000,1.116021e-002,0.000000e+000,3,9.685523e-001,1.825000e+000,,,,,,,,,,,,,,,,,,0,4.000000e+000,1.000000e+000,5,1,1.651001e-002,0,1,0,
1545084579.954,,6.745605e+003,3.000038e+002,4.858280e-003,0.000000e+000,1.106256e-002,0.000000e+000,3,9.696026e-001,1.825000e+000,,,,,,,,,,,,,,,,,,0,4.000000e+000,1.000000e+000,5,1,8.300781e-003,0,1,0,
1545085167.240,,2.690551e+004,2.999997e+002,1.048353e-002,0.000000e+000,7.657197e-003,0.000000e+000,3,9.725571e-001,1.825000e+000,,,,,,,,,,,,,,,,,,0,4.000000e+000,1.000000e+000,5,1,0.000000e+000,0,0,0,
1545086045.301,,1.839743e+003,2.999997e+002,1.976161e-003,0.000000e+000,1.343751e-002,0.000000e+000,3,9.680929e-001,1.825000e+000,,,,,,,,,,,,,,,,,,0,4.000000e+000,1.000000e+000,5,1,0.000000e+000,0,1,0,
1545086509.999,,4.788117e+003,2.999997e+002,4.124361e-003,0.000000e+000,1.123949e-002,0.000000e+000,3,9.690817e-001,1.825000e+000,,,,,,,,,,,,,,,,,,0,4.000000e+000,1.000000e+000,5,1,0.000000e+000,0,0,0,
1545087032.248,,1.049998e+004,2.999997e+002,6.010029e-003,0.000000e+000,9.608589e-003,0.000000e+000,3,9.706104e-001,1.825000e+000,,,,,,,,,,,,,,,,,,0,4.000000e+000,1.000000e+000,5,1,0.000000e+000,0,1,0,
1545087980.408,,-8.267966e+002,2.999997e+002,5.515037e-005,0.000000e+000,1.885201e-001,0.000000e+000,3,9.651598e-001,1.825000e+000,,,,,,,,,,,,,,,,,,0,4.000000e+000,1.000000e+000,5,1,0.000000e+000,0,0,0,
1545088457.654,,3.318231e+003,2.999997e+002,3.138470e-003,0.000000e+000,1.099342e-002,0.000000e+000,3,9.681195e-001,1.825000e+000,,,,,,,,,,,,,,,,,,0,4.000000e+000,1.000000e+000,5,1,0.000000e+000,0,1,0,
1545088927.283,,6.745460e+003,2.999997e+002,4.842964e-003,0.000000e+000,1.039242e-002,0.000000e+000,3,9.697728e-001,1.825000e+000,,,,,,,,,,,,,,,,,,0,4.000000e+000,1.000000e+000,5,1,0.000000e+000,0,1,0,
1545089516.759,,2.690480e+004,2.999997e+002,1.048277e-002,0.000000e+000,7.293009e-003,0.000000e+000,3,9.725173e-001,1.825000e+000,,,,,,,,,,,,,,,,,,0,4.000000e+000,1.000000e+000,5,1,0.000000e+000,0,0,0,
1545090404.101,,1.839671e+003,3.000038e+002,1.795902e-003,0.000000e+000,1.299635e-002,0.000000e+000,3,9.680690e-001,1.825000e+000,,,,,,,,,,,,,,,,,,0,4.000000e+000,1.000000e+000,5,1,8.300781e-003,0,1,0,
1545090865.489,,4.787973e+003,2.999998e+002,4.079614e-003,0.000000e+000,1.055822e-002,0.000000e+000,3,9.689577e-001,1.825000e+000,,,,,,,,,,,,,,,,,,0,4.000000e+000,1.000000e+000,5,1,1.651001e-002,0,0,0,
1545091384.570,,1.050084e+004,2.999997e+002,6.004469e-003,0.000000e+000,9.811095e-003,0.000000e+000,3,9.705372e-001,1.825000e+000,,,,,,,,,,,,,,,,,,0,4.000000e+000,1.000000e+000,5,1,0.000000e+000,0,1,0,
1545092324.918,,-8.268256e+002,2.999997e+002,-1.421893e-004,0.000000e+000,-5.134647e-002,0.000000e+000,3,9.756056e-001,1.825000e+000,,,,,,,,,,,,,,,,,,0,4.000000e+000,1.000000e+000,5,1,0.000000e+000,0,0,0,
1545092823.197,,3.318158e+003,2.999915e+002,2.981598e-003,0.000000e+000,9.565408e-003,0.000000e+000,3,9.691077e-001,1.825000e+000,,,,,,,,,,,,,,,,,,0,4.000000e+000,1.000000e+000,5,1,0.000000e+000,0,1,0,
1545093288.724,,6.745460e+003,3.000121e+002,4.823757e-003,0.000000e+000,9.960405e-003,0.000000e+000,3,9.697349e-001,1.825000e+000,,,,,,,,,,,,,,,,,,0,4.000000e+000,1.000000e+000,5,1,8.209229e-003,0,1,0,
1545093884.702,,2.690480e+004,2.999956e+002,1.048114e-002,0.000000e+000,6.882161e-003,0.000000e+000,3,9.725523e-001,1.825000e+000,,,,,,,,,,,,,,,,,,0,4.000000e+000,1.000000e+000,5,1,8.209229e-003,0,0,0,
1545094776.093,,1.839671e+003,3.000038e+002,1.604496e-003,0.000000e+000,1.202125e-002,0.000000e+000,3,9.682592e-001,1.825000e+000,,,,,,,,,,,,,,,,,,0,4.000000e+000,1.000000e+000,5,1,8.300781e-003,0,1,0,
1545095236.712,,4.787973e+003,2.999997e+002,4.002635e-003,0.000000e+000,1.007351e-002,0.000000e+000,3,9.689962e-001,1.825000e+000,,,,,,,,,,,,,,,,,,0,4.000000e+000,1.000000e+000,5,1,0.000000e+000,0,0,0,
1545095753.020,,1.049998e+004,2.999997e+002,5.996625e-003,0.000000e+000,8.830607e-003,0.000000e+000,3,9.705957e-001,1.825000e+000,,,,,,,,,,,,,,,,,,0,4.000000e+000,1.000000e+000,5,1,0.000000e+000,0,1,0,
1545096694.396,,-8.267966e+002,2.999997e+002,-3.358827e-004,0.000000e+000,-1.339760e-002,0.000000e+000,3,9.703854e-001,1.825000e+000,,,,,,,,,,,,,,,,,,0,4.000000e+000,1.000000e+000,5,1,0.000000e+000,0,0,0,
1545097190.127,,3.318158e+003,2.999956e+002,2.821201e-003,0.000000e+000,9.333696e-003,0.000000e+000,3,9.692227e-001,1.825000e+000,,,,,,,,,,,,,,,,,,0,4.000000e+000,1.000000e+000,5,1,8.209229e-003,0,0,0,
1545097658.974,,6.745460e+003,2.999997e+002,4.804269e-003,0.000000e+000,9.473875e-003,0.000000e+000,3,9.696439e-001,1.825000e+000,,,,,,,,,,,,,,,,,,0,4.000000e+000,1.000000e+000,5,1,0.000000e+000,0,1,0,
1545098244.669,,2.690480e+004,2.999997e+002,1.047968e-002,0.000000e+000,6.626049e-003,0.000000e+000,3,9.725356e-001,1.825000e+000,,,,,,,,,,,,,,,,,,0,4.000000e+000,1.000000e+000,5,1,0.000000e+000,0,0,0,
1545099177.456,,1.839743e+003,3.000038e+002,1.409739e-003,0.000000e+000,1.137947e-002,0.000000e+000,3,9.687220e-001,1.825000e+000,,,,,,,,,,,,,,,,,,0,4.000000e+000,1.000000e+000,5,1,8.300781e-003,0,1,0,
1545099637.501,,4.787973e+003,2.999956e+002,3.893584e-003,0.000000e+000,9.523687e-003,0.000000e+000,3,9.693075e-001,1.825000e+000,,,,,,,,,,,,,,,,,,0,4.000000e+000,1.000000e+000,5,1,8.209229e-003,0,0,0,
1545100164.862,,1.049998e+004,2.999997e+002,5.989209e-003,0.000000e+000,8.795886e-003,0.000000e+000,3,9.705362e-001,1.825000e+000,,,,,,,,,,,,,,,,,,0,4.000000e+000,1.000000e+000,5,1,0.000000e+000,0,1,0,
1545101101.170,,-1.353747e+003,2.999997e+002,-7.794647e-004,0.000000e+000,1.304412e-003,0.000000e+000,3,9.697454e-001,1.825000e+000,,,,,,,,,,,,,,,,,,0,4.000000e+000,1.000000e+000,5,1,0.000000e+000,0,1,0,
1545101619.211,,3.178659e+003,2.999997e+002,2.530651e-003,0.000000e+000,8.906345e-003,0.000000e+000,3,9.692447e-001,1.825000e+000,,,,,,,,,,,,,,,,,,0,4.000000e+000,1.000000e+000,5,1,0.000000e+000,0,0,0,
1545102088.010,,6.501587e+003,3.000038e+002,4.689354e-003,0.000000e+000,9.654938e-003,0.000000e+000,3,9.696259e-001,1.825000e+000,,,,,,,,,,,,,,,,,,0,4.000000e+000,1.000000e+000,5,1,8.300781e-003,0,1,0,
1545102662.801,,2.337970e+004,2.999997e+002,9.544424e-003,0.000000e+000,6.886621e-003,0.000000e+000,3,9.722779e-001,1.825000e+000,,,,,,,,,,,,,,,,,,0,4.000000e+000,1.000000e+000,5,1,0.000000e+000,0,0,0,
1545103580.636,,1.492294e+003,3.000038e+002,9.164569e-004,0.000000e+000,1.221941e-002,0.000000e+000,3,9.687172e-001,1.825000e+000,,,,,,,,,,,,,,,,,,0,4.000000e+000,1.000000e+000,5,1,8.300781e-003,0,1,0,
1545104050.665,,4.470664e+003,2.999997e+002,3.532062e-003,0.000000e+000,9.182248e-003,0.000000e+000,3,9.692391e-001,1.825000e+000,,,,,,,,,,,,,,,,,,0,4.000000e+000,1.000000e+000,5,1,0.000000e+000,0,1,0,
1545104563.989,,9.434856e+003,2.999956e+002,5.657809e-003,0.000000e+000,8.896699e-003,0.000000e+000,3,9.703740e-001,1.825000e+000,,,,,,,,,,,,,,,,,,0,4.000000e+000,1.000000e+000,5,1,8.209229e-003,0,0,0,
1545105504.636,,-2.852242e+003,2.999997e+002,-1.590744e-003,0.000000e+000,5.213311e-003,0.000000e+000,3,9.703149e-001,1.825000e+000,,,,,,,,,,,,,,,,,,0,4.000000e+000,1.000000e+000,5,1,0.000000e+000,0,1,0,
1545106011.958,,2.898501e+003,2.999998e+002,2.084781e-003,0.000000e+000,8.230126e-003,0.000000e+000,3,9.691768e-001,1.825000e+000,,,,,,,,,,,,,,,,,,0,4.000000e+000,1.000000e+000,5,1,1.651001e-002,0,0,0,
1545106482.567,,6.057788e+003,3.000038e+002,4.476456e-003,0.000000e+000,9.197991e-003,0.000000e+000,3,9.695662e-001,1.825000e+000,,,,,,,,,,,,,,,,,,0,4.000000e+000,1.000000e+000,5,1,8.300781e-003,0,1,0,
1545107036.132,,1.830925e+004,2.999997e+002,8.178056e-003,0.000000e+000,7.172739e-003,0.000000e+000,3,9.718617e-001,1.825000e+000,,,,,,,,,,,,,,,,,,0,4.000000e+000,1.000000e+000,5,1,0.000000e+000,0,1,0,
1545107962.527,,1.084923e+003,3.000038e+002,3.912067e-004,0.000000e+000,1.823970e-002,0.000000e+000,3,9.666869e-001,1.825000e+000,,,,,,,,,,,,,,,,,,0,4.000000e+000,1.000000e+000,5,1,8.300781e-003,0,0,0,
1545108443.850,,4.171642e+003,2.999956e+002,3.140795e-003,0.000000e+000,7.798391e-003,0.000000e+000,3,9.697564e-001,1.825000e+000,,,,,,,,,,,,,,,,,,0,4.000000e+000,1.000000e+000,5,1,8.209229e-003,0,1,0,
1545108965.174,,8.575301e+003,2.999997e+002,5.373054e-003,0.000000e+000,8.870094e-003,0.000000e+000,3,9.702237e-001,1.825000e+000,,,,,,,,,,,,,,,,,,0,4.000000e+000,1.000000e+000,5,1,0.000000e+000,0,1,0,
1545109875.359,,-5.359130e+003,2.999997e+002,-2.670333e-003,0.000000e+000,6.024955e-003,0.000000e+000,3,9.711263e-001,1.825000e+000,,,,,,,,,,,,,,,,,,0,4.000000e+000,1.000000e+000,5,1,0.000000e+000,0,1,0,
1545110478.785,,2.614513e+003,3.000038e+002,1.630410e-003,0.000000e+000,6.632520e-003,0.000000e+000,3,9.693811e-001,1.825000e+000,,,,,,,,,,,,,,,,,,0,4.000000e+000,1.000000e+000,5,1,8.300781e-003,0,1,0,
1545110929.516,,5.662128e+003,2.999997e+002,4.170063e-003,0.000000e+000,9.077712e-003,0.000000e+000,3,9.693867e-001,1.825000e+000,,,,,,,,,,,,,,,,,,0,4.000000e+000,1.000000e+000,5,1,0.000000e+000,0,0,0,
1545111475.250,,1.500158e+004,3.000038e+002,7.263409e-003,0.000000e+000,7.084514e-003,0.000000e+000,3,9.713405e-001,1.825000e+000,,,,,,,,,,,,,,,,,,0,4.000000e+000,1.000000e+000,5,1,8.300781e-003,0,1,0,
1545112431.126,,6.031046e+002,2.999997e+002,-1.598412e-004,0.000000e+000,-8.794694e-003,0.000000e+000,3,9.633713e-001,1.825000e+000,,,,,,,,,,,,,,,,,,0,4.000000e+000,1.000000e+000,5,1,0.000000e+000,0,0,0,
1545112953.286,,3.880280e+003,2.999997e+002,2.726779e-003,0.000000e+000,6.564169e-003,0.000000e+000,3,9.692227e-001,1.825000e+000,,,,,,,,,,,,,,,,,,0,4.000000e+000,1.000000e+000,5,1,0.000000e+000,0,1,0,
1545113471.246,,7.872596e+003,2.999997e+002,5.120189e-003,0.000000e+000,8.162051e-003,0.000000e+000,3,9.700768e-001,1.825000e+000,,,,,,,,,,,,,,,,,,0,4.000000e+000,1.000000e+000,5,1,0.000000e+000,0,1,0,
1545114120.989,,5.037918e+004,2.999956e+002,1.657798e-002,0.000000e+000,4.049384e-003,0.000000e+000,3,9.736003e-001,1.825000e+000,,,,,,,,,,,,,,,,,,0,4.000000e+000,1.000000e+000,5,1,8.209229e-003,0,0,0,
1545115008.887,,2.317442e+003,2.999997e+002,1.160616e-003,0.000000e+000,4.325357e-003,0.000000e+000,3,9.702294e-001,1.825000e+000,,,,,,,,,,,,,,,,,,0,4.000000e+000,1.000000e+000,5,1,0.000000e+000,0,1,0,
1545115477.829,,5.294801e+003,2.999956e+002,3.789968e-003,0.000000e+000,7.665209e-003,0.000000e+000,3,9.696313e-001,1.825000e+000,,,,,,,,,,,,,,,,,,0,4.000000e+000,1.000000e+000,5,1,8.209229e-003,0,0,0,
1545116002.799,,1.275309e+004,2.999956e+002,6.620894e-003,0.000000e+000,6.841207e-003,0.000000e+000,3,9.710478e-001,1.825000e+000,,,,,,,,,,,,,,,,,,0,4.000000e+000,1.000000e+000,5,1,8.209229e-003,0,1,0,
1545116998.698,,-3.811471e+002,2.999956e+002,-9.829187e-004,0.000000e+000,6.758680e-003,0.000000e+000,3,9.668949e-001,1.825000e+000,,,,,,,,,,,,,,,,,,0,4.000000e+000,1.000000e+000,5,1,8.209229e-003,0,0,0,
1545117524.975,,3.456647e+003,2.999956e+002,2.153437e-003,0.000000e+000,5.025848e-003,0.000000e+000,3,9.701141e-001,1.825000e+000,,,,,,,,,,,,,,,,,,0,4.000000e+000,1.000000e+000,5,1,8.209229e-003,0,0,0,
1545118041.198,,6.996128e+003,2.999998e+002,4.757081e-003,0.000000e+000,7.727882e-003,0.000000e+000,3,9.699481e-001,1.825000e+000,,,,,,,,,,,,,,,,,,0,4.000000e+000,1.000000e+000,5,1,1.651001e-002,0,1,0,
1545118615.052,,3.127050e+004,3.000038e+002,1.162143e-002,0.000000e+000,4.654805e-003,0.000000e+000,3,9.728361e-001,1.825000e+000,,,,,,,,,,,,,,,,,,0,4.000000e+000,1.000000e+000,5,1,8.300781e-003,0,0,0,
1545119547.811,,1.668079e+003,3.000038e+002,3.722953e-004,0.000000e+000,1.708290e-003,0.000000e+000,3,9.666091e-001,1.825000e+000,,,,,,,,,,,,,,,,,,0,4.000000e+000,1.000000e+000,5,1,8.300781e-003,0,1,0,
1545120018.910,,4.626066e+003,2.999997e+002,3.122074e-003,0.000000e+000,7.073497e-003,0.000000e+000,3,9.694484e-001,1.825000e+000,,,,,,,,,,,,,,,,,,0,4.000000e+000,1.000000e+000,5,1,0.000000e+000,0,0,0,
1545120535.795,,9.936772e+003,2.999997e+002,5.771833e-003,0.000000e+000,7.266933e-003,0.000000e+000,3,9.705583e-001,1.825000e+000,,,,,,,,,,,,,,,,,,0,4.000000e+000,1.000000e+000,5,1,0.000000e+000,0,1,0,
1545121537.868,,-2.852170e+003,2.999997e+002,-2.241574e-003,0.000000e+000,7.028436e-003,0.000000e+000,3,9.693621e-001,1.825000e+000,,,,,,,,,,,,,,,,,,0,4.000000e+000,1.000000e+000,5,1,0.000000e+000,0,0,0,
1545122028.136,,2.898429e+003,2.999956e+002,1.426904e-003,0.000000e+000,2.800271e-003,0.000000e+000,3,9.706827e-001,1.825000e+000,,,,,,,,,,,,,,,,,,0,4.000000e+000,1.000000e+000,5,1,8.209229e-003,0,1,0,
1545122493.603,,6.057645e+003,2.999997e+002,4.109228e-003,0.000000e+000,7.573846e-003,0.000000e+000,3,9.695750e-001,1.825000e+000,,,,,,,,,,,,,,,,,,0,4.000000e+000,1.000000e+000,5,1,0.000000e+000,0,1,0,
1545123044.199,,1.830853e+004,2.999997e+002,8.166142e-003,0.000000e+000,6.067085e-003,0.000000e+000,3,9.717876e-001,1.825000e+000,,,,,,,,,,,,,,,,,,0,4.000000e+000,1.000000e+000,5,1,0.000000e+000,0,0,0,
1545124040.855,,8.529332e+002,2.999997e+002,-4.742862e-004,0.000000e+000,1.339346e-002,0.000000e+000,3,9.610587e-001,1.825000e+000,,,,,,,,,,,,,,,,,,0,4.000000e+000,1.000000e+000,5,1,0.000000e+000,0,1,0,
1545124556.736,,4.022889e+003,2.999997e+002,2.417211e-003,0.000000e+000,5.121723e-003,0.000000e+000,3,9.701662e-001,1.825000e+000,,,,,,,,,,,,,,,,,,0,4.000000e+000,1.000000e+000,5,1,0.000000e+000,0,0,0,
1545125078.277,,8.212457e+003,2.999997e+002,5.177165e-003,0.000000e+000,7.818449e-003,0.000000e+000,3,9.699790e-001,1.825000e+000,,,,,,,,,,,,,,,,,,0,4.000000e+000,1.000000e+000,5,1,0.000000e+000,0,1,0,
1545126002.797,,-8.210144e+003,2.999997e+002,-4.196877e-003,0.000000e+000,6.434622e-003,0.000000e+000,3,9.711431e-001,1.825000e+000,,,,,,,,,,,,,,,,,,0,4.000000e+000,1.000000e+000,5,1,0.000000e+000,0,1,0,
1545126566.199,,2.317442e+003,2.999997e+002,6.694191e-004,0.000000e+000,-3.180802e-003,0.000000e+000,3,9.720061e-001,1.825000e+000,,,,,,,,,,,,,,,,,,0,4.000000e+000,1.000000e+000,5,1,0.000000e+000,0,1,0,
1545127054.218,,5.294801e+003,3.000038e+002,3.419778e-003,0.000000e+000,6.698665e-003,0.000000e+000,3,9.699575e-001,1.825000e+000,,,,,,,,,,,,,,,,,,0,4.000000e+000,1.000000e+000,5,1,8.300781e-003,0,1,0,
1545127584.127,,1.275367e+004,2.999997e+002,6.602873e-003,0.000000e+000,7.120257e-003,0.000000e+000,3,9.710498e-001,1.825000e+000,,,,,,,,,,,,,,,,,,0,4.000000e+000,1.000000e+000,5,1,0.000000e+000,0,0,0,
1545128582.712,,-3.811615e+002,2.999997e+002,-1.454380e-003,0.000000e+000,8.559066e-003,0.000000e+000,3,9.670910e-001,1.825000e+000,,,,,,,,,,,,,,,,,,0,4.000000e+000,1.000000e+000,5,1,0.000000e+000,0,1,0,
1545129078.014,,3.456720e+003,2.999997e+002,1.690191e-003,0.000000e+000,3.284453e-003,0.000000e+000,3,9.708137e-001,1.825000e+000,,,,,,,,,,,,,,,,,,0,4.000000e+000,1.000000e+000,5,1,0.000000e+000,0,0,0,
1545129605.059,,6.995694e+003,2.999956e+002,4.486811e-003,0.000000e+000,7.584469e-003,0.000000e+000,3,9.701049e-001,1.825000e+000,,,,,,,,,,,,,,,,,,0,4.000000e+000,1.000000e+000,5,1,8.209229e-003,0,1,0,
1545130172.165,,3.127123e+004,2.999997e+002,1.161982e-002,0.000000e+000,5.089651e-003,0.000000e+000,3,9.727957e-001,1.825000e+000,,,,,,,,,,,,,,,,,,0,4.000000e+000,1.000000e+000,5,1,0.000000e+000,0,1,0,
1545131114.500,,1.492294e+003,2.999956e+002,-2.660870e-004,0.000000e+000,2.985782e-002,0.000000e+000,3,9.587994e-001,1.825000e+000,,,,,,,,,,,,,,,,,,0,4.000000e+000,1.000000e+000,5,1,8.209229e-003,0,1,0,
1545131692.823,,4.470664e+003,2.999997e+002,2.569687e-003,0.000000e+000,5.134037e-003,0.000000e+000,3,9.704384e-001,1.825000e+000,,,,,,,,,,,,,,,,,,0,4.000000e+000,1.000000e+000,5,1,0.000000e+000,0,1,0,
1545132214.498,,9.433989e+003,2.999956e+002,5.562650e-003,0.000000e+000,7.890751e-003,0.000000e+000,3,9.704398e-001,1.825000e+000,,,,,,,,,,,,,,,,,,0,4.000000e+000,1.000000e+000,5,1,8.209229e-003,0,0,0,
1545133217.107,,-5.359130e+003,3.000080e+002,-3.559207e-003,0.000000e+000,7.913172e-003,0.000000e+000,3,9.699633e-001,1.825000e+000,,,,,,,,,,,,,,,,,,0,4.000000e+000,1.000000e+000,5,1,0.000000e+000,0,1,0,
1545133750.919,,2.614513e+003,2.999997e+002,6.696237e-004,0.000000e+000,-6.081974e-003,0.000000e+000,3,9.727550e-001,1.825000e+000,,,,,,,,,,,,,,,,,,0,4.000000e+000,1.000000e+000,5,1,0.000000e+000,0,0,0,
1545134230.652,,5.662273e+003,2.999997e+002,3.466061e-003,0.000000e+000,6.861598e-003,0.000000e+000,3,9.699878e-001,1.825000e+000,,,,,,,,,,,,,,,,,,0,4.000000e+000,1.000000e+000,5,1,0.000000e+000,0,1,0,
1545134765.500,,1.500100e+004,2.999956e+002,7.237350e-003,0.000000e+000,7.095451e-003,0.000000e+000,3,9.714030e-001,1.825000e+000,,,,,,,,,,,,,,,,,,0,4.000000e+000,1.000000e+000,5,1,8.209229e-003,0,1,0,
1545135778.410,,4.784938e+000,3.000038e+002,-1.512301e-003,0.000000e+000,1.051429e-002,0.000000e+000,3,9.668562e-001,1.825000e+000,,,,,,,,,,,,,,,,,,0,4.000000e+000,1.000000e+000,5,1,8.300781e-003,0,1,0,
1545136266.855,,3.597087e+003,2.999997e+002,1.556772e-003,0.000000e+000,2.519753e-003,0.000000e+000,3,9.711514e-001,1.825000e+000,,,,,,,,,,,,,,,,,,0,4.000000e+000,1.000000e+000,5,1,0.000000e+000,0,1,0,
1545136787.224,,7.270358e+003,2.999956e+002,4.448379e-003,0.000000e+000,7.924924e-003,0.000000e+000,3,9.701574e-001,1.825000e+000,,,,,,,,,,,,,,,,,,0,4.000000e+000,1.000000e+000,5,1,8.209229e-003,0,0,0,
1545137371.865,,3.658020e+004,3.000038e+002,1.300617e-002,0.000000e+000,5.061246e-003,0.000000e+000,3,9.731202e-001,1.825000e+000,,,,,,,,,,,,,,,,,,0,4.000000e+000,1.000000e+000,5,1,8.300781e-003,0,1,0,
1545138299.295,,1.668079e+003,2.999997e+002,-3.997110e-004,0.000000e+000,2.824362e-002,0.000000e+000,3,9.597830e-001,1.825000e+000,,,,,,,,,,,,,,,,,,0,4.000000e+000,1.000000e+000,5,1,0.000000e+000,0,0,0,
1545138763.476,,4.626211e+003,2.999997e+002,2.446204e-003,0.000000e+000,4.389139e-003,0.000000e+000,3,9.703978e-001,1.825000e+000,,,,,,,,,,,,,,,,,,0,4.000000e+000,1.000000e+000,5,1,0.000000e+000,0,1,0,
1545139292.049,,9.937058e+003,2.999956e+002,5.658347e-003,0.000000e+000,8.158339e-003,0.000000e+000,3,9.706399e-001,1.825000e+000,,,,,,,,,,,,,,,,,,0,4.000000e+000,1.000000e+000,5,1,8.209229e-003,0,1,0,
1545140308.869,,-3.994627e+003,2.999997e+002,-3.360551e-003,0.000000e+000,9.231196e-003,0.000000e+000,3,9.690940e-001,1.825000e+000,,,,,,,,,,,,,,,,,,0,4.000000e+000,1.000000e+000,5,1,0.000000e+000,0,1,0,
1545140818.763,,2.757049e+003,2.999997e+002,5.320256e-004,0.000000e+000,-1.158386e-002,0.000000e+000,3,9.753614e-001,1.825000e+000,,,,,,,,,,,,,,,,,,0,4.000000e+000,1.000000e+000,5,1,0.000000e+000,0,1,0,
1545141304.388,,5.859019e+003,2.999998e+002,3.379687e-003,0.000000e+000,7.347548e-003,0.000000e+000,3,9.703097e-001,1.825000e+000,,,,,,,,,,,,,,,,,,0,4.000000e+000,1.000000e+000,5,1,1.651001e-002,0,0,0,
1545141853.935,,1.648852e+004,2.999997e+002,7.647225e-003,0.000000e+000,7.177716e-003,0.000000e+000,3,9.715226e-001,1.825000e+000,,,,,,,,,,,,,,,,,,0,4.000000e+000,1.000000e+000,5,1,0.000000e+000,0,1,0,
1545142887.490,,4.784938e+000,2.999956e+002,-1.779215e-003,0.000000e+000,1.124251e-002,0.000000e+000,3,9.667924e-001,1.825000e+000,,,,,,,,,,,,,,,,,,0,4.000000e+000,1.000000e+000,5,1,8.209229e-003,0,0,0,
1545143349.257,,3.597160e+003,2.999997e+002,1.289765e-003,0.000000e+000,7.392411e-004,0.000000e+000,3,9.713359e-001,1.825000e+000,,,,,,,,,,,,,,,,,,0,4.000000e+000,1.000000e+000,5,1,0.000000e+000,0,1,0,
1545143862.943,,7.270358e+003,2.999956e+002,4.245013e-003,0.000000e+000,7.851609e-003,0.000000e+000,3,9.703432e-001,1.825000e+000,,,,,,,,,,,,,,,,,,0,4.000000e+000,1.000000e+000,5,1,8.209229e-003,0,0,0,
1545144460.976,,3.658020e+004,2.999956e+002,1.300660e-002,0.000000e+000,5.265257e-003,0.000000e+000,3,9.730856e-001,1.825000e+000,,,,,,,,,,,,,,,,,,0,4.000000e+000,1.000000e+000,5,1,8.209229e-003,0,1,0,
1545145405.147,,1.492294e+003,2.999997e+002,-8.210823e-004,0.000000e+000,7.423609e-003,0.000000e+000,3,9.377488e-001,1.825000e+000,,,,,,,,,,,,,,,,,,0,4.000000e+000,1.000000e+000,5,1,0.000000e+000,0,1,0,
1545145894.093,,4.470664e+003,2.999915e+002,2.053738e-003,0.000000e+000,3.348821e-003,0.000000e+000,3,9.705611e-001,1.825000e+000,,,,,,,,,,,,,,,,,,0,4.000000e+000,1.000000e+000,5,1,0.000000e+000,0,0,0,
1545146425.463,,9.434278e+003,3.000038e+002,5.285487e-003,0.000000e+000,8.354316e-003,0.000000e+000,3,9.705646e-001,1.825000e+000,,,,,,,,,,,,,,,,,,0,4.000000e+000,1.000000e+000,5,1,8.300781e-003,0,1,0,
1545147398.297,,-6.949436e+003,2.999998e+002,-4.547327e-003,0.000000e+000,8.669299e-003,0.000000e+000,3,9.700424e-001,1.825000e+000,,,,,,,,,,,,,,,,,,0,4.000000e+000,1.000000e+000,5,1,1.651001e-002,0,0,0,
1545147960.358,,2.470026e+003,2.999997e+002,-2.493460e-005,0.000000e+000,8.095549e-001,0.000000e+000,3,8.594505e-001,1.825000e+000,,,,,,,,,,,,,,,,,,0,4.000000e+000,1.000000e+000,5,1,0.000000e+000,0,1,0,
1545148447.790,,5.472609e+003,2.999997e+002,2.851708e-003,0.000000e+000,5.673366e-003,0.000000e+000,3,9.705152e-001,1.825000e+000,,,,,,,,,,,,,,,,,,0,4.000000e+000,1.000000e+000,5,1,0.000000e+000,0,0,0,
1545148976.612,,1.377542e+004,2.999997e+002,6.851799e-003,0.000000e+000,7.870409e-003,0.000000e+000,3,9.711910e-001,1.825000e+000,,,,,,,,,,,,,,,,,,0,4.000000e+000,1.000000e+000,5,1,0.000000e+000,0,1,0,
1545150024.686,,-1.353718e+003,2.999956e+002,-2.693175e-003,0.000000e+000,1.113264e-002,0.000000e+000,3,9.677318e-001,1.825000e+000,,,,,,,,,,,,,,,,,,0,4.000000e+000,1.000000e+000,5,1,8.209229e-003,0,0,0,
1545150511.985,,3.178659e+003,2.999956e+002,6.170064e-004,0.000000e+000,-1.078745e-002,0.000000e+000,3,9.753475e-001,1.825000e+000,,,,,,,,,,,,,,,,,,0,4.000000e+000,1.000000e+000,5,1,8.209229e-003,0,1,0,
1545150977.823,,6.501732e+003,2.999997e+002,3.549684e-003,0.000000e+000,7.339452e-003,0.000000e+000,3,9.705606e-001,1.825000e+000,,,,,,,,,,,,,,,,,,0,4.000000e+000,1.000000e+000,5,1,0.000000e+000,0,1,0,
1545151556.941,,2.337970e+004,2.999956e+002,9.521684e-003,0.000000e+000,6.764277e-003,0.000000e+000,3,9.722431e-001,1.825000e+000,,,,,,,,,,,,,,,,,,0,4.000000e+000,1.000000e+000,5,1,8.209229e-003,0,0,0,
1545152575.570,,6.031479e+002,2.999956e+002,-1.715265e-003,0.000000e+000,1.307119e-002,0.000000e+000,3,9.664777e-001,1.825000e+000,,,,,,,,,,,,,,,,,,0,4.000000e+000,1.000000e+000,5,1,8.209229e-003,0,1,0,
1545153094.908,,3.880354e+003,2.999956e+002,1.262479e-003,0.000000e+000,-6.658263e-004,0.000000e+000,3,9.729137e-001,1.825000e+000,,,,,,,,,,,,,,,,,,0,4.000000e+000,1.000000e+000,5,1,8.209229e-003,0,0,0,
1545153619.199,,7.873029e+003,2.999997e+002,4.332835e-003,0.000000e+000,8.224594e-003,0.000000e+000,3,9.706065e-001,1.825000e+000,,,,,,,,,,,,,,,,,,0,4.000000e+000,1.000000e+000,5,1,0.000000e+000,0,1,0,
1545154259.998,,5.038207e+004,2.999997e+002,1.657983e-002,0.000000e+000,5.335446e-003,0.000000e+000,3,9.735717e-001,1.825000e+000,,,,,,,,,,,,,,,,,,0,4.000000e+000,1.000000e+000,5,1,0.000000e+000,0,1,0,
1545155188.150,,1.668079e+003,2.999997e+002,-9.762563e-004,0.000000e+000,1.973861e-002,0.000000e+000,3,9.643216e-001,1.825000e+000,,,,,,,,,,,,,,,,,,0,4.000000e+000,1.000000e+000,5,1,0.000000e+000,0,1,0,
1545155766.570,,4.626355e+003,3.000038e+002,1.908746e-003,0.000000e+000,3.309073e-003,0.000000e+000,3,9.709523e-001,1.825000e+000,,,,,,,,,,,,,,,,,,0,4.000000e+000,1.000000e+000,5,1,8.300781e-003,0,1,0,
1545156295.704,,9.937058e+003,2.999997e+002,5.292179e-003,0.000000e+000,8.451073e-003,0.000000e+000,3,9.707319e-001,1.825000e+000,,,,,,,,,,,,,,,,,,0,4.000000e+000,1.000000e+000,5,1,0.000000e+000,0,0,0,
1545157324.080,,-8.961855e+003,3.000038e+002,-5.401753e-003,0.000000e+000,8.929406e-003,0.000000e+000,3,9.703770e-001,1.825000e+000,,,,,,,,,,,,,,,,,,0,4.000000e+000,1.000000e+000,5,1,8.300781e-003,0,1,0,
1545157892.519,,2.317514e+003,2.999956e+002,-4.413343e-004,0.000000e+000,3.760761e-002,0.000000e+000,3,9.583624e-001,1.825000e+000,,,,,,,,,,,,,,,,,,0,4.000000e+000,1.000000e+000,5,1,8.209229e-003,0,0,0,
1545158355.863,,5.295090e+003,2.999997e+002,2.441701e-003,0.000000e+000,5.883279e-003,0.000000e+000,3,9.711652e-001,1.825000e+000,,,,,,,,,,,,,,,,,,0,4.000000e+000,1.000000e+000,5,1,0.000000e+000,0,1,0,
1545158883.944,,1.275395e+004,2.999997e+002,6.344766e-003,0.000000e+000,8.283596e-003,0.000000e+000,3,9.712306e-001,1.825000e+000,,,,,,,,,,,,,,,,,,0,4.000000e+000,1.000000e+000,5,1,0.000000e+000,0,1,0,
1545160007.954,,-2.852315e+003,2.999997e+002,-3.515542e-003,0.000000e+000,1.069785e-002,0.000000e+000,3,9.683411e-001,1.825000e+000,,,,,,,,,,,,,,,,,,0,4.000000e+000,1.000000e+000,5,1,0.000000e+000,0,1,0,
1545160500.941,,2.898501e+003,2.999997e+002,7.759038e-005,0.000000e+000,-1.522663e-001,0.000000e+000,3,9.259657e-001,1.825000e+000,,,,,,,,,,,,,,,,,,0,4.000000e+000,1.000000e+000,5,1,0.000000e+000,0,1,0,
1545161000.914,,6.057788e+003,2.999997e+002,3.004245e-003,0.000000e+000,6.801334e-003,0.000000e+000,3,9.709223e-001,1.825000e+000,,,,,,,,,,,,,,,,,,0,4.000000e+000,1.000000e+000,5,1,0.000000e+000,0,0,0,
1545161560.656,,1.830925e+004,2.999997e+002,8.076316e-003,0.000000e+000,7.583035e-003,0.000000e+000,3,9.719371e-001,1.825000e+000,,,,,,,,,,,,,,,,,,0,4.000000e+000,1.000000e+000,5,1,0.000000e+000,0,1,0,
1545162685.566,,-8.267966e+002,2.999997e+002,-2.750052e-003,0.000000e+000,1.212727e-002,0.000000e+000,3,9.674421e-001,1.825000e+000,,,,,,,,,,,,,,,,,,0,4.000000e+000,1.000000e+000,5,1,0.000000e+000,0,1,0,
1545163194.085,,3.318231e+003,3.000038e+002,4.596740e-004,0.000000e+000,-1.912734e-002,0.000000e+000,3,9.779297e-001,1.825000e+000,,,,,,,,,,,,,,,,,,0,4.000000e+000,1.000000e+000,5,1,8.300781e-003,0,1,0,
1545163675.486,,6.745605e+003,2.999998e+002,3.456631e-003,0.000000e+000,7.618017e-003,0.000000e+000,3,9.709369e-001,1.825000e+000,,,,,,,,,,,,,,,,,,0,4.000000e+000,1.000000e+000,5,1,1.651001e-002,0,0,0,
1545164277.770,,2.690551e+004,2.999915e+002,1.045545e-002,0.000000e+000,6.742778e-003,0.000000e+000,3,9.725172e-001,1.825000e+000,,,,,,,,,,,,,,,,,,0,4.000000e+000,1.000000e+000,5,1,0.000000e+000,0,1,0,
1545165445.623,,4.770481e+000,2.999997e+002,-2.350362e-003,0.000000e+000,1.193836e-002,0.000000e+000,3,9.671252e-001,1.825000e+000,,,,,,,,,,,,,,,,,,0,4.000000e+000,1.000000e+000,5,1,0.000000e+000,0,0,0,
1545165948.089,,3.597232e+003,2.999998e+002,7.099628e-004,0.000000e+000,-1.020527e-002,0.000000e+000,3,9.762839e-001,1.825000e+000,,,,,,,,,,,,,,,,,,0,4.000000e+000,1.000000e+000,5,1,1.651001e-002,0,1,0,
1545166454.046,,7.271515e+003,2.999997e+002,3.762569e-003,0.000000e+000,8.175788e-003,0.000000e+000,3,9.708378e-001,1.825000e+000,,,,,,,,,,,,,,,,,,0,4.000000e+000,1.000000e+000,5,1,0.000000e+000,0,1,0,
1545167044.368,,3.658091e+004,2.999956e+002,1.300395e-002,0.000000e+000,6.069756e-003,0.000000e+000,3,9.730700e-001,1.825000e+000,,,,,,,,,,,,,,,,,,0,4.000000e+000,1.000000e+000,5,1,8.209229e-003,0,1,0,
1545168200.720,,3.160661e+002,2.999997e+002,-2.189503e-003,0.000000e+000,1.334432e-002,0.000000e+000,3,9.660243e-001,1.825000e+000,,,,,,,,,,,,,,,,,,0,4.000000e+000,1.000000e+000,5,1,0.000000e+000,0,0,0,
1545168672.302,,3.738757e+003,2.999997e+002,8.265794e-004,0.000000e+000,-6.772086e-003,0.000000e+000,3,9.745083e-001,1.825000e+000,,,,,,,,,,,,,,,,,,0,4.000000e+000,1.000000e+000,5,1,0.000000e+000,0,1,0,
1545169200.699,,7.555141e+003,2.999997e+002,3.914236e-003,0.000000e+000,8.290149e-003,0.000000e+000,3,9.708191e-001,1.825000e+000,,,,,,,,,,,,,,,,,,0,4.000000e+000,1.000000e+000,5,1,0.000000e+000,0,1,0,
1545169822.158,,4.289531e+004,2.999997e+002,1.464645e-002,0.000000e+000,5.921679e-003,0.000000e+000,3,9.732782e-001,1.825000e+000,,,,,,,,,,,,,,,,,,0,4.000000e+000,1.000000e+000,5,1,0.000000e+000,0,0,0,
1545171019.233,,3.160372e+002,2.999956e+002,-2.210169e-003,0.000000e+000,1.180550e-002,0.000000e+000,3,9.663509e-001,1.825000e+000,,,,,,,,,,,,,,,,,,0,4.000000e+000,1.000000e+000,5,1,8.209229e-003,0,1,0,
1545171494.937,,3.738829e+003,2.999997e+002,8.032988e-004,0.000000e+000,-6.331405e-003,0.000000e+000,3,9.747981e-001,1.825000e+000,,,,,,,,,,,,,,,,,,0,4.000000e+000,1.000000e+000,5,1,0.000000e+000,0,0,0,
1545172005.193,,7.555141e+003,2.999997e+002,3.898462e-003,0.000000e+000,8.208139e-003,0.000000e+000,3,9.707637e-001,1.825000e+000,,,,,,,,,,,,,,,,,,0,4.000000e+000,1.000000e+000,5,1,0.000000e+000,0,1,0,
1545172636.540,,4.289386e+004,2.999956e+002,1.464635e-002,0.000000e+000,5.969550e-003,0.000000e+000,3,9.733086e-001,1.825000e+000,,,,,,,,,,,,,,,,,,0,4.000000e+000,1.000000e+000,5,1,8.209229e-003,0,0,0,
1545173896.941,,3.159794e+002,3.000038e+002,-2.223426e-003,0.000000e+000,1.209187e-002,0.000000e+000,3,9.666378e-001,1.825000e+000,,,,,,,,,,,,,,,,,,0,4.000000e+000,1.000000e+000,5,1,8.300781e-003,0,1,0,
1545174406.647,,3.738757e+003,2.999915e+002,7.913947e-004,0.000000e+000,-8.472527e-003,0.000000e+000,3,9.719532e-001,1.825000e+000,,,,,,,,,,,,,,,,,,0,4.000000e+000,1.000000e+000,5,1,0.000000e+000,0,0,0,
1545174950.491,,7.555286e+003,2.999956e+002,3.888481e-003,0.000000e+000,8.053646e-003,0.000000e+000,3,9.710457e-001,1.825000e+000,,,,,,,,,,,,,,,,,,0,4.000000e+000,1.000000e+000,5,1,8.209229e-003,0,1,0,
1545175564.247,,4.289386e+004,2.999956e+002,1.464089e-002,0.000000e+000,6.067533e-003,0.000000e+000,3,9.732834e-001,1.825000e+000,,,,,,,,,,,,,,,,,,0,4.000000e+000,1.000000e+000,5,1,8.209229e-003,0,1,0,
1545175620.002,,5.038352e+004,2.999997e+002,1.658235e-002,0.000000e+000,5.825135e-003,0.000000e+000,3,9.735205e-001,1.825000e+000,,,,,,,,,,,,,,,,,,0,4.000000e+000,1.000000e+000,5,1,0.000000e+000,0,0,0,