File: Irregular grid FORC measurements/Fig. 8g, h, i Zebra rock red mpms remFORC test.rso.dat
[Header]
TITLE,MPMS RSO Measurement
BYAPP,MPMS Measurement,1.1,Summary
FILEOPENTIME, 1545177343.653000 12/19/2018, 10:55:43 AM

INFO, APPNAME, MPMS MultiVu Application, Revision 1.60,  Build 081

INFO, NAME, Zebra Rock Red xiang
INFO, WEIGHT, 1.000
INFO, AREA, 1.000
INFO, LENGTH, 1.000
INFO, SHAPE,
INFO, COMMENT,
INFO, SEQUENCE FILE: Zebra Rock Red xiang LOOP_hys-osci-noover_ 5T_after LT refilled.rso.datMPMS remFORC.seq


INFO, BACKGROUND DATA FILE:, None


STARTUPAXIS,X,4,LINEAR,AUTO,0.000000,0.000000
STARTUPAXIS,Y1,5,LINEAR,AUTO,0.000000,0.000000


STARTUPGROUP,Longitudinal
FIELDGROUP,Longitudinal,1,2,3,4,5,6,7,8,9,10,11,19,20,21,22,23,35
FIELDGROUP,Transverse,1,2,3,4,12,13,14,15,16,17,18,24,25,26,27,28,35

PLOT_APPEARANCE,ALL,HORZ_GRID_ON,VERT_GRID_ON,MARKERS_AND_LINES

[Data]
Time,Comment,Field (Oe),Temperature (K),Long Moment (emu),Long Scan Std Dev,Long Offset (cm),Long Offset Std Dev,Long Algorithm,Long Reg Fit,Long Reg Factor,Trans Moment (emu),Trans Scan Std Dev,Trans Offset (cm),Trans Offset Std Dev,Trans Algorithm,Trans Reg Fit,Trans Reg Factor,Long Moment [w/o ABS] (emu),Long Scan Std Dev [w/o ABS],Long Offset [w/o ABS] (cm),Long Offset Std Dev [w/o ABS],Long Reg Fit [w/o ABS],Trans Moment [w/o ABS] (emu),Trans Scan Std Dev [w/o ABS],Trans Offset [w/o ABS] (cm),Trans Offset Std Dev [w/o ABS],Trans Reg Fit [w/o ABS],RSO Position (deg),Amplitude (cm),Frequency,Cycles to Average,Scans per Measurement,Delta Temp (K),Error,EC Comp. Running,Using ABS,
1545177343.652,,4.244355e+004,2.999997e+002,1.453258e-002,0.000000e+000,6.023253e-003,0.000000e+000,3,9.733108e-001,1.825000e+000,,,,,,,,,,,,,,,,,,0,4.000000e+000,1.000000e+000,5,1,0.000000e+000,0,1,0,
1545187440.238,,2.337898e+004,2.999997e+002,9.552019e-003,0.000000e+000,6.632827e-003,0.000000e+000,3,9.723161e-001,1.825000e+000,,,,,,,,,,,,,,,,,,0,4.000000e+000,1.000000e+000,5,1,0.000000e+000,0,1,0,
1545195749.015,,1.377426e+004,2.999956e+002,6.953253e-003,0.000000e+000,7.157262e-003,0.000000e+000,3,9.712733e-001,1.825000e+000,,,,,,,,,,,,,,,,,,0,4.000000e+000,1.000000e+000,5,1,8.209229e-003,0,0,0,
1545202683.180,,1.499955e+004,2.999997e+002,7.292073e-003,0.000000e+000,6.492021e-003,0.000000e+000,3,9.714350e-001,1.825000e+000,,,,,,,,,,,,,,,,,,0,4.000000e+000,1.000000e+000,5,1,0.000000e+000,0,1,0,
1545209060.927,,1.049824e+004,2.999956e+002,6.029189e-003,0.000000e+000,7.358529e-003,0.000000e+000,3,9.706535e-001,1.825000e+000,,,,,,,,,,,,,,,,,,0,4.000000e+000,1.000000e+000,5,1,8.209229e-003,0,1,0,
1545215001.786,,6.279399e+003,2.999956e+002,4.775147e-003,0.000000e+000,8.213859e-003,0.000000e+000,3,9.696755e-001,1.825000e+000,,,,,,,,,,,,,,,,,,0,4.000000e+000,1.000000e+000,5,1,8.209229e-003,0,0,0,
1545219574.723,,2.056367e+004,2.999956e+002,8.799792e-003,0.000000e+000,5.992236e-003,0.000000e+000,3,9.720983e-001,1.825000e+000,,,,,,,,,,,,,,,,,,0,4.000000e+000,1.000000e+000,5,1,8.209229e-003,0,1,0,
1545223934.908,,6.057500e+003,2.999956e+002,4.706136e-003,0.000000e+000,8.845828e-003,0.000000e+000,3,9.696366e-001,1.825000e+000,,,,,,,,,,,,,,,,,,0,4.000000e+000,1.000000e+000,5,1,8.209229e-003,0,0,0,
1545228256.114,,1.830781e+004,2.999956e+002,8.193566e-003,0.000000e+000,6.812393e-003,0.000000e+000,3,9.718439e-001,1.825000e+000,,,,,,,,,,,,,,,,,,0,4.000000e+000,1.000000e+000,5,1,8.209229e-003,0,0,0,
1545232734.046,,4.470520e+003,2.999997e+002,4.193334e-003,0.000000e+000,9.767991e-003,0.000000e+000,3,9.691253e-001,1.825000e+000,,,,,,,,,,,,,,,,,,0,4.000000e+000,1.000000e+000,5,1,0.000000e+000,0,0,0,
1545235535.976,,9.433121e+003,2.999956e+002,5.722295e-003,0.000000e+000,8.719898e-003,0.000000e+000,3,9.703326e-001,1.825000e+000,,,,,,,,,,,,,,,,,,0,4.000000e+000,1.000000e+000,5,1,8.209229e-003,0,1,0,
1545241595.898,,2.317442e+003,2.999997e+002,3.440296e-003,0.000000e+000,1.066637e-002,0.000000e+000,3,9.681297e-001,1.825000e+000,,,,,,,,,,,,,,,,,,0,4.000000e+000,1.000000e+000,5,1,0.000000e+000,0,1,0,
1545243197.741,,5.294801e+003,2.999998e+002,4.463695e-003,0.000000e+000,9.911504e-003,0.000000e+000,3,9.693359e-001,1.825000e+000,,,,,,,,,,,,,,,,,,0,4.000000e+000,1.000000e+000,5,1,1.651001e-002,0,1,0,
1545246739.702,,1.275279e+004,2.999956e+002,6.669438e-003,0.000000e+000,8.330955e-003,0.000000e+000,3,9.710206e-001,1.825000e+000,,,,,,,,,,,,,,,,,,0,4.000000e+000,1.000000e+000,5,1,8.209229e-003,0,0,0,
1545251938.232,,2.614441e+003,2.999997e+002,3.549762e-003,0.000000e+000,1.089690e-002,0.000000e+000,3,9.682699e-001,1.825000e+000,,,,,,,,,,,,,,,,,,0,4.000000e+000,1.000000e+000,5,1,0.000000e+000,0,1,0,
1545253598.341,,5.662128e+003,2.999997e+002,4.580823e-003,0.000000e+000,1.010226e-002,0.000000e+000,3,9.694685e-001,1.825000e+000,,,,,,,,,,,,,,,,,,0,4.000000e+000,1.000000e+000,5,1,0.000000e+000,0,1,0,
1545257493.367,,1.499984e+004,2.999956e+002,7.293695e-003,0.000000e+000,7.807614e-003,0.000000e+000,3,9.713798e-001,1.825000e+000,,,,,,,,,,,,,,,,,,0,4.000000e+000,1.000000e+000,5,1,8.209229e-003,0,1,0,
1545262221.089,,2.469880e+003,2.999997e+002,3.496181e-003,0.000000e+000,1.020286e-002,0.000000e+000,3,9.681775e-001,1.825000e+000,,,,,,,,,,,,,,,,,,0,4.000000e+000,1.000000e+000,5,1,0.000000e+000,0,1,0,
1545263858.930,,5.472321e+003,2.999997e+002,4.520266e-003,0.000000e+000,9.254015e-003,0.000000e+000,3,9.694147e-001,1.825000e+000,,,,,,,,,,,,,,,,,,0,4.000000e+000,1.000000e+000,5,1,0.000000e+000,0,1,0,
1545267555.077,,1.377397e+004,3.000038e+002,6.953930e-003,0.000000e+000,7.103636e-003,0.000000e+000,3,9.711623e-001,1.825000e+000,,,,,,,,,,,,,,,,,,0,4.000000e+000,1.000000e+000,5,1,8.300781e-003,0,1,0,
1545272470.173,,2.164787e+003,2.999997e+002,3.381925e-003,0.000000e+000,9.325299e-003,0.000000e+000,3,9.680557e-001,1.825000e+000,,,,,,,,,,,,,,,,,,0,4.000000e+000,1.000000e+000,5,1,0.000000e+000,0,1,0,
1545274032.922,,5.118003e+003,2.999956e+002,4.405809e-003,0.000000e+000,8.340305e-003,0.000000e+000,3,9.693522e-001,1.825000e+000,,,,,,,,,,,,,,,,,,0,4.000000e+000,1.000000e+000,5,1,8.209229e-003,0,1,0,
1545277416.765,,1.188775e+004,2.999997e+002,6.425905e-003,0.000000e+000,6.444876e-003,0.000000e+000,3,9.708937e-001,1.825000e+000,,,,,,,,,,,,,,,,,,0,4.000000e+000,1.000000e+000,5,1,0.000000e+000,0,1,0,
1545282725.786,,1.492149e+003,2.999915e+002,3.118242e-003,0.000000e+000,8.531112e-003,0.000000e+000,3,9.678240e-001,1.825000e+000,,,,,,,,,,,,,,,,,,0,4.000000e+000,1.000000e+000,5,1,0.000000e+000,0,0,0,
1545284184.892,,4.470230e+003,2.999997e+002,4.192821e-003,0.000000e+000,7.563951e-003,0.000000e+000,3,9.691018e-001,1.825000e+000,,,,,,,,,,,,,,,,,,0,4.000000e+000,1.000000e+000,5,1,0.000000e+000,0,1,0,
1545286984.018,,9.432543e+003,2.999997e+002,5.722186e-003,0.000000e+000,6.096584e-003,0.000000e+000,3,9.703575e-001,1.825000e+000,,,,,,,,,,,,,,,,,,0,4.000000e+000,1.000000e+000,5,1,0.000000e+000,0,1,0,
1545293010.305,,6.030178e+002,2.999956e+002,2.719979e-003,0.000000e+000,8.246747e-003,0.000000e+000,3,9.673808e-001,1.825000e+000,,,,,,,,,,,,,,,,,,0,4.000000e+000,1.000000e+000,5,1,8.209229e-003,0,1,0,
1545294348.776,,3.880136e+003,2.999997e+002,3.994830e-003,0.000000e+000,7.208947e-003,0.000000e+000,3,9.688950e-001,1.825000e+000,,,,,,,,,,,,,,,,,,0,4.000000e+000,1.000000e+000,5,1,0.000000e+000,0,0,0,
1545296629.475,,7.872595e+003,2.999997e+002,5.260663e-003,0.000000e+000,6.324250e-003,0.000000e+000,3,9.699630e-001,1.825000e+000,,,,,,,,,,,,,,,,,,0,4.000000e+000,1.000000e+000,5,1,0.000000e+000,0,1,0,
1545303041.509,,5.037918e+004,2.999956e+002,1.658658e-002,0.000000e+000,2.418216e-003,0.000000e+000,3,9.736171e-001,1.825000e+000,,,,,,,,,,,,,,,,,,0,4.000000e+000,1.000000e+000,5,1,8.209229e-003,0,1,0,
1545304540.996,,3.178442e+003,2.999997e+002,3.745123e-003,0.000000e+000,8.114148e-003,0.000000e+000,3,9.686232e-001,1.825000e+000,,,,,,,,,,,,,,,,,,0,4.000000e+000,1.000000e+000,5,1,0.000000e+000,0,1,0,
1545306311.051,,6.501299e+003,2.999998e+002,4.841891e-003,0.000000e+000,7.381032e-003,0.000000e+000,3,9.697997e-001,1.825000e+000,,,,,,,,,,,,,,,,,,0,4.000000e+000,1.000000e+000,5,1,1.651001e-002,0,1,0,
1545311169.867,,2.337898e+004,2.999915e+002,9.552215e-003,0.000000e+000,4.620136e-003,0.000000e+000,3,9.723594e-001,1.825000e+000,,,,,,,,,,,,,,,,,,0,4.000000e+000,1.000000e+000,5,1,0.000000e+000,0,0,0,
1545314751.881,,2.317369e+003,3.000038e+002,3.419756e-003,0.000000e+000,8.999199e-003,0.000000e+000,3,9.681926e-001,1.825000e+000,,,,,,,,,,,,,,,,,,0,4.000000e+000,1.000000e+000,5,1,8.300781e-003,0,1,0,
1545316350.195,,5.294657e+003,3.000038e+002,4.458384e-003,0.000000e+000,8.225567e-003,0.000000e+000,3,9.693923e-001,1.825000e+000,,,,,,,,,,,,,,,,,,0,4.000000e+000,1.000000e+000,5,1,8.300781e-003,0,1,0,
1545319906.180,,1.275279e+004,2.999997e+002,6.668584e-003,0.000000e+000,6.872497e-003,0.000000e+000,3,9.710295e-001,1.825000e+000,,,,,,,,,,,,,,,,,,0,4.000000e+000,1.000000e+000,5,1,0.000000e+000,0,0,0,
1545325001.723,,1.288637e+003,2.999956e+002,2.982725e-003,0.000000e+000,1.009132e-002,0.000000e+000,3,9.675283e-001,1.825000e+000,,,,,,,,,,,,,,,,,,0,4.000000e+000,1.000000e+000,5,1,8.209229e-003,0,1,0,
1545326442.985,,4.320900e+003,2.999956e+002,4.134029e-003,0.000000e+000,9.062773e-003,0.000000e+000,3,9.690089e-001,1.825000e+000,,,,,,,,,,,,,,,,,,0,4.000000e+000,1.000000e+000,5,1,8.209229e-003,0,1,0,
1545329102.682,,8.983250e+003,2.999956e+002,5.589205e-003,0.000000e+000,8.201342e-003,0.000000e+000,3,9.702770e-001,1.825000e+000,,,,,,,,,,,,,,,,,,0,4.000000e+000,1.000000e+000,5,1,8.209229e-003,0,0,0,
1545335322.355,,-3.812483e+002,3.000038e+002,2.038447e-003,0.000000e+000,1.243001e-002,0.000000e+000,3,9.670970e-001,1.825000e+000,,,,,,,,,,,,,,,,,,0,4.000000e+000,1.000000e+000,5,1,8.300781e-003,0,0,0,
1545336579.621,,3.456575e+003,2.999956e+002,3.832128e-003,0.000000e+000,1.004117e-002,0.000000e+000,3,9.686529e-001,1.825000e+000,,,,,,,,,,,,,,,,,,0,4.000000e+000,1.000000e+000,5,1,8.209229e-003,0,0,0,
1545338477.492,,6.995694e+003,2.999956e+002,4.991709e-003,0.000000e+000,9.152533e-003,0.000000e+000,3,9.697267e-001,1.825000e+000,,,,,,,,,,,,,,,,,,0,4.000000e+000,1.000000e+000,5,1,8.209229e-003,0,0,0,
1545343873.829,,3.127123e+004,2.999997e+002,1.163700e-002,0.000000e+000,5.902067e-003,0.000000e+000,3,9.727672e-001,1.825000e+000,,,,,,,,,,,,,,,,,,0,4.000000e+000,1.000000e+000,5,1,0.000000e+000,0,1,0,
1545346741.477,,2.469954e+003,3.000038e+002,3.454311e-003,0.000000e+000,1.087155e-002,0.000000e+000,3,9.682192e-001,1.825000e+000,,,,,,,,,,,,,,,,,,0,4.000000e+000,1.000000e+000,5,1,8.300781e-003,0,1,0,
1545348371.448,,5.472465e+003,2.999997e+002,4.511436e-003,0.000000e+000,9.982564e-003,0.000000e+000,3,9.694069e-001,1.825000e+000,,,,,,,,,,,,,,,,,,0,4.000000e+000,1.000000e+000,5,1,0.000000e+000,0,1,0,
1545352100.788,,1.377484e+004,2.999997e+002,6.954946e-003,0.000000e+000,8.037825e-003,0.000000e+000,3,9.711992e-001,1.825000e+000,,,,,,,,,,,,,,,,,,0,4.000000e+000,1.000000e+000,5,1,0.000000e+000,0,1,0,
1545357012.476,,1.288637e+003,2.999997e+002,2.884028e-003,0.000000e+000,1.178085e-002,0.000000e+000,3,9.675702e-001,1.825000e+000,,,,,,,,,,,,,,,,,,0,4.000000e+000,1.000000e+000,5,1,0.000000e+000,0,1,0,
1545358447.973,,4.321044e+003,2.999997e+002,4.124647e-003,0.000000e+000,1.025199e-002,0.000000e+000,3,9.689997e-001,1.825000e+000,,,,,,,,,,,,,,,,,,0,4.000000e+000,1.000000e+000,5,1,0.000000e+000,0,1,0,
1545361110.564,,8.983250e+003,2.999997e+002,5.586011e-003,0.000000e+000,9.213243e-003,0.000000e+000,3,9.703355e-001,1.825000e+000,,,,,,,,,,,,,,,,,,0,4.000000e+000,1.000000e+000,5,1,0.000000e+000,0,0,0,
1545367323.191,,-8.268256e+002,2.999997e+002,1.634201e-003,0.000000e+000,1.486339e-002,0.000000e+000,3,9.667079e-001,1.825000e+000,,,,,,,,,,,,,,,,,,0,4.000000e+000,1.000000e+000,5,1,0.000000e+000,0,0,0,
1545368541.446,,3.318086e+003,2.999956e+002,3.764570e-003,0.000000e+000,1.021206e-002,0.000000e+000,3,9.685838e-001,1.825000e+000,,,,,,,,,,,,,,,,,,0,4.000000e+000,1.000000e+000,5,1,8.209229e-003,0,0,0,
1545370340.039,,6.745316e+003,2.999997e+002,4.912566e-003,0.000000e+000,9.339456e-003,0.000000e+000,3,9.697716e-001,1.825000e+000,,,,,,,,,,,,,,,,,,0,4.000000e+000,1.000000e+000,5,1,0.000000e+000,0,0,0,
1545375468.786,,2.690407e+004,2.999997e+002,1.049126e-002,0.000000e+000,5.901380e-003,0.000000e+000,3,9.725691e-001,1.825000e+000,,,,,,,,,,,,,,,,,,0,4.000000e+000,1.000000e+000,5,1,0.000000e+000,0,1,0,
1545378717.254,,2.164931e+003,2.999997e+002,3.284993e-003,0.000000e+000,1.048964e-002,0.000000e+000,3,9.679974e-001,1.825000e+000,,,,,,,,,,,,,,,,,,0,4.000000e+000,1.000000e+000,5,1,0.000000e+000,0,1,0,
1545380293.385,,5.118148e+003,3.000038e+002,4.386247e-003,0.000000e+000,9.951709e-003,0.000000e+000,3,9.694771e-001,1.825000e+000,,,,,,,,,,,,,,,,,,0,4.000000e+000,1.000000e+000,5,1,8.300781e-003,0,1,0,
1545383681.977,,1.188862e+004,2.999997e+002,6.424812e-003,0.000000e+000,8.286095e-003,0.000000e+000,3,9.708958e-001,1.825000e+000,,,,,,,,,,,,,,,,,,0,4.000000e+000,1.000000e+000,5,1,0.000000e+000,0,0,0,
1545389009.288,,6.030323e+002,2.999956e+002,2.283722e-003,0.000000e+000,1.392856e-002,0.000000e+000,3,9.671866e-001,1.825000e+000,,,,,,,,,,,,,,,,,,0,4.000000e+000,1.000000e+000,5,1,8.209229e-003,0,1,0,
1545390327.035,,3.880281e+003,2.999997e+002,3.955685e-003,0.000000e+000,1.047154e-002,0.000000e+000,3,9.689201e-001,1.825000e+000,,,,,,,,,,,,,,,,,,0,4.000000e+000,1.000000e+000,5,1,0.000000e+000,0,1,0,
1545392601.109,,7.872452e+003,2.999997e+002,5.253140e-003,0.000000e+000,9.780671e-003,0.000000e+000,3,9.700307e-001,1.825000e+000,,,,,,,,,,,,,,,,,,0,4.000000e+000,1.000000e+000,5,1,0.000000e+000,0,0,0,
1545398995.361,,5.038207e+004,2.999956e+002,1.661077e-002,0.000000e+000,6.174249e-003,0.000000e+000,3,9.723989e-001,1.825000e+000,,,,,,,,,,,,,,,,,,0,4.000000e+000,1.000000e+000,5,1,8.209229e-003,0,0,0,
1545400458.530,,2.757049e+003,2.999997e+002,3.508030e-003,0.000000e+000,1.134428e-002,0.000000e+000,3,9.683260e-001,1.825000e+000,,,,,,,,,,,,,,,,,,0,4.000000e+000,1.000000e+000,5,1,0.000000e+000,0,0,0,
1545402144.890,,5.859019e+003,2.999956e+002,4.623908e-003,0.000000e+000,1.053167e-002,0.000000e+000,3,9.694776e-001,1.825000e+000,,,,,,,,,,,,,,,,,,0,4.000000e+000,1.000000e+000,5,1,8.209229e-003,0,1,0,
1545406257.321,,1.648824e+004,2.999997e+002,7.703128e-003,0.000000e+000,8.701174e-003,0.000000e+000,3,9.715557e-001,1.825000e+000,,,,,,,,,,,,,,,,,,0,4.000000e+000,1.000000e+000,5,1,0.000000e+000,0,0,0,
1545410700.185,,1.492264e+003,2.999997e+002,2.734909e-003,0.000000e+000,1.380851e-002,0.000000e+000,3,9.676852e-001,1.825000e+000,,,,,,,,,,,,,,,,,,0,4.000000e+000,1.000000e+000,5,1,0.000000e+000,0,0,0,
1545412162.525,,4.470664e+003,2.999956e+002,4.154341e-003,0.000000e+000,1.156044e-002,0.000000e+000,3,9.689997e-001,1.825000e+000,,,,,,,,,,,,,,,,,,0,4.000000e+000,1.000000e+000,5,1,8.209229e-003,0,0,0,
1545414992.215,,9.433699e+003,2.999956e+002,5.717254e-003,0.000000e+000,1.056627e-002,0.000000e+000,3,9.702315e-001,1.825000e+000,,,,,,,,,,,,,,,,,,0,4.000000e+000,1.000000e+000,5,1,8.209229e-003,0,0,0,
1545421060.061,,-8.268544e+002,2.999915e+002,1.267722e-003,0.000000e+000,2.024441e-002,0.000000e+000,3,9.664999e-001,1.825000e+000,,,,,,,,,,,,,,,,,,0,4.000000e+000,1.000000e+000,5,1,0.000000e+000,0,0,0,
1545422309.777,,3.318159e+003,2.999956e+002,3.706275e-003,0.000000e+000,1.249151e-002,0.000000e+000,3,9.685506e-001,1.825000e+000,,,,,,,,,,,,,,,,,,0,4.000000e+000,1.000000e+000,5,1,8.209229e-003,0,0,0,
1545424110.433,,6.745606e+003,2.999997e+002,4.902180e-003,0.000000e+000,1.157483e-002,0.000000e+000,3,9.697238e-001,1.825000e+000,,,,,,,,,,,,,,,,,,0,4.000000e+000,1.000000e+000,5,1,0.000000e+000,0,1,0,
1545429229.551,,2.690551e+004,2.999956e+002,1.049475e-002,0.000000e+000,8.610769e-003,0.000000e+000,3,9.724849e-001,1.825000e+000,,,,,,,,,,,,,,,,,,0,4.000000e+000,1.000000e+000,5,1,8.209229e-003,0,0,0,
1545432498.596,,2.165003e+003,2.999956e+002,3.068026e-003,0.000000e+000,1.350034e-002,0.000000e+000,3,9.680208e-001,1.825000e+000,,,,,,,,,,,,,,,,,,0,4.000000e+000,1.000000e+000,5,1,8.209229e-003,0,0,0,
1545434073.957,,5.118438e+003,2.999956e+002,4.363984e-003,0.000000e+000,1.198334e-002,0.000000e+000,3,9.692857e-001,1.825000e+000,,,,,,,,,,,,,,,,,,0,4.000000e+000,1.000000e+000,5,1,8.209229e-003,0,0,0,
1545437478.355,,1.188890e+004,2.999997e+002,6.423115e-003,0.000000e+000,1.044513e-002,0.000000e+000,3,9.708277e-001,1.825000e+000,,,,,,,,,,,,,,,,,,0,4.000000e+000,1.000000e+000,5,1,0.000000e+000,0,1,0,
1545442881.767,,3.159649e+002,2.999956e+002,1.711855e-003,0.000000e+000,1.724453e-002,0.000000e+000,3,9.674755e-001,1.825000e+000,,,,,,,,,,,,,,,,,,0,4.000000e+000,1.000000e+000,5,1,8.209229e-003,0,0,0,
1545444192.242,,3.738684e+003,2.999997e+002,3.849433e-003,0.000000e+000,1.201898e-002,0.000000e+000,3,9.687960e-001,1.825000e+000,,,,,,,,,,,,,,,,,,0,4.000000e+000,1.000000e+000,5,1,0.000000e+000,0,0,0,
1545446324.654,,7.554708e+003,2.999956e+002,5.145233e-003,0.000000e+000,1.094748e-002,0.000000e+000,3,9.698216e-001,1.825000e+000,,,,,,,,,,,,,,,,,,0,4.000000e+000,1.000000e+000,5,1,8.209229e-003,0,1,0,
1545452328.725,,4.289386e+004,2.999915e+002,1.467194e-002,0.000000e+000,6.019964e-003,0.000000e+000,3,9.732752e-001,1.825000e+000,,,,,,,,,,,,,,,,,,0,4.000000e+000,1.000000e+000,5,1,0.000000e+000,0,1,0,
1545454391.546,,2.469954e+003,2.999997e+002,3.153514e-003,0.000000e+000,1.166364e-002,0.000000e+000,3,9.683448e-001,1.825000e+000,,,,,,,,,,,,,,,,,,0,4.000000e+000,1.000000e+000,5,1,0.000000e+000,0,1,0,
1545456039.304,,5.472465e+003,2.999997e+002,4.470947e-003,0.000000e+000,1.042104e-002,0.000000e+000,3,9.694003e-001,1.825000e+000,,,,,,,,,,,,,,,,,,0,4.000000e+000,1.000000e+000,5,1,0.000000e+000,0,1,0,
1545459776.242,,1.377513e+004,2.999956e+002,6.952146e-003,0.000000e+000,8.376041e-003,0.000000e+000,3,9.713668e-001,1.825000e+000,,,,,,,,,,,,,,,,,,0,4.000000e+000,1.000000e+000,5,1,8.209229e-003,0,1,0,
1545464754.204,,8.528464e+002,3.000038e+002,1.909510e-003,0.000000e+000,1.578421e-002,0.000000e+000,3,9.673302e-001,1.825000e+000,,,,,,,,,,,,,,,,,,0,4.000000e+000,1.000000e+000,5,1,8.300781e-003,0,1,0,
1545466123.443,,4.022889e+003,2.999997e+002,3.934111e-003,0.000000e+000,1.064140e-002,0.000000e+000,3,9.688667e-001,1.825000e+000,,,,,,,,,,,,,,,,,,0,4.000000e+000,1.000000e+000,5,1,0.000000e+000,0,1,0,
1545468524.203,,8.210433e+003,3.000038e+002,5.341263e-003,0.000000e+000,9.909400e-003,0.000000e+000,3,9.699956e-001,1.825000e+000,,,,,,,,,,,,,,,,,,0,4.000000e+000,1.000000e+000,5,1,8.300781e-003,0,0,0,
1545475082.564,,-3.318159e+003,2.999956e+002,-3.076463e-004,0.000000e+000,-3.210050e-002,0.000000e+000,3,9.838859e-001,1.825000e+000,,,,,,,,,,,,,,,,,,0,4.000000e+000,1.000000e+000,5,1,8.209229e-003,0,1,0,
1545476307.544,,2.757049e+003,3.000038e+002,3.231442e-003,0.000000e+000,1.180900e-002,0.000000e+000,3,9.683626e-001,1.825000e+000,,,,,,,,,,,,,,,,,,0,4.000000e+000,1.000000e+000,5,1,8.300781e-003,0,1,0,
1545477992.532,,5.859019e+003,2.999997e+002,4.589375e-003,0.000000e+000,1.099878e-002,0.000000e+000,3,9.695202e-001,1.825000e+000,,,,,,,,,,,,,,,,,,0,4.000000e+000,1.000000e+000,5,1,0.000000e+000,0,1,0,
1545482098.864,,1.648824e+004,2.999956e+002,7.709261e-003,0.000000e+000,9.693645e-003,0.000000e+000,3,9.708937e-001,1.825000e+000,,,,,,,,,,,,,,,,,,0,4.000000e+000,1.000000e+000,5,1,8.209229e-003,0,1,0,
1545486634.170,,1.288666e+003,2.999956e+002,2.059649e-003,0.000000e+000,1.586831e-002,0.000000e+000,3,9.676190e-001,1.825000e+000,,,,,,,,,,,,,,,,,,0,4.000000e+000,1.000000e+000,5,1,8.209229e-003,0,1,0,
1545488084.984,,4.321189e+003,2.999956e+002,4.021100e-003,0.000000e+000,1.192839e-002,0.000000e+000,3,9.690801e-001,1.825000e+000,,,,,,,,,,,,,,,,,,0,4.000000e+000,1.000000e+000,5,1,8.209229e-003,0,1,0,
1545490751.079,,8.983829e+003,2.999997e+002,5.568952e-003,0.000000e+000,1.105149e-002,0.000000e+000,3,9.702210e-001,1.825000e+000,,,,,,,,,,,,,,,,,,0,4.000000e+000,1.000000e+000,5,1,0.000000e+000,0,1,0,
1545497024.762,,-1.991314e+003,2.999997e+002,1.342167e-004,0.000000e+000,1.056288e-001,0.000000e+000,3,9.478589e-001,1.825000e+000,,,,,,,,,,,,,,,,,,0,4.000000e+000,1.000000e+000,5,1,0.000000e+000,0,1,0,
1545498231.313,,3.040097e+003,2.999956e+002,3.309420e-003,0.000000e+000,1.274315e-002,0.000000e+000,3,9.685863e-001,1.825000e+000,,,,,,,,,,,,,,,,,,0,4.000000e+000,1.000000e+000,5,1,8.209229e-003,0,1,0,
1545499972.255,,6.279833e+003,2.999998e+002,4.717534e-003,0.000000e+000,1.214026e-002,0.000000e+000,3,9.696025e-001,1.825000e+000,,,,,,,,,,,,,,,,,,0,4.000000e+000,1.000000e+000,5,1,1.651001e-002,0,1,0,
1545504544.761,,2.056512e+004,2.999956e+002,8.806254e-003,0.000000e+000,9.881807e-003,0.000000e+000,3,9.719896e-001,1.825000e+000,,,,,,,,,,,,,,,,,,0,4.000000e+000,1.000000e+000,5,1,8.209229e-003,0,1,0,
1545508514.824,,1.668049e+003,2.999997e+002,2.175988e-003,0.000000e+000,1.621537e-002,0.000000e+000,3,9.677445e-001,1.825000e+000,,,,,,,,,,,,,,,,,,0,4.000000e+000,1.000000e+000,5,1,0.000000e+000,0,1,0,
1545510006.262,,4.626499e+003,3.000038e+002,4.111319e-003,0.000000e+000,1.298622e-002,0.000000e+000,3,9.691532e-001,1.825000e+000,,,,,,,,,,,,,,,,,,0,4.000000e+000,1.000000e+000,5,1,8.300781e-003,0,1,0,
1545512946.743,,9.936194e+003,2.999956e+002,5.846703e-003,0.000000e+000,1.183049e-002,0.000000e+000,3,9.704565e-001,1.825000e+000,,,,,,,,,,,,,,,,,,0,4.000000e+000,1.000000e+000,5,1,8.209229e-003,0,1,0,
1545518914.721,,-8.268256e+002,2.999956e+002,4.859767e-004,0.000000e+000,3.431776e-002,0.000000e+000,3,9.657196e-001,1.825000e+000,,,,,,,,,,,,,,,,,,0,4.000000e+000,1.000000e+000,5,1,8.209229e-003,0,1,0,
1545520152.752,,3.318159e+003,2.999997e+002,3.385068e-003,0.000000e+000,1.260155e-002,0.000000e+000,3,9.687715e-001,1.825000e+000,,,,,,,,,,,,,,,,,,0,4.000000e+000,1.000000e+000,5,1,0.000000e+000,0,1,0,
1545521955.609,,6.745606e+003,2.999997e+002,4.859251e-003,0.000000e+000,1.194112e-002,0.000000e+000,3,9.697003e-001,1.825000e+000,,,,,,,,,,,,,,,,,,0,4.000000e+000,1.000000e+000,5,1,0.000000e+000,0,1,0,
1545527090.741,,2.690479e+004,2.999915e+002,1.049490e-002,0.000000e+000,8.312340e-003,0.000000e+000,3,9.725130e-001,1.825000e+000,,,,,,,,,,,,,,,,,,0,4.000000e+000,1.000000e+000,5,1,0.000000e+000,0,0,0,
1545530470.072,,1.839671e+003,2.999915e+002,2.130634e-003,0.000000e+000,1.399135e-002,0.000000e+000,3,9.682343e-001,1.825000e+000,,,,,,,,,,,,,,,,,,0,4.000000e+000,1.000000e+000,5,1,0.000000e+000,0,1,0,
1545531987.356,,4.787972e+003,2.999956e+002,4.143002e-003,0.000000e+000,1.124822e-002,0.000000e+000,3,9.692230e-001,1.825000e+000,,,,,,,,,,,,,,,,,,0,4.000000e+000,1.000000e+000,5,1,8.209229e-003,0,1,0,
1545535059.918,,1.049882e+004,3.000079e+002,6.007423e-003,0.000000e+000,9.765646e-003,0.000000e+000,3,9.705790e-001,1.825000e+000,,,,,,,,,,,,,,,,,,0,4.000000e+000,1.000000e+000,5,1,1.651001e-002,0,1,0,
1545540879.986,,-8.268112e+002,2.999997e+002,2.857852e-004,0.000000e+000,4.623321e-002,0.000000e+000,3,9.650761e-001,1.825000e+000,,,,,,,,,,,,,,,,,,0,4.000000e+000,1.000000e+000,5,1,0.000000e+000,0,1,0,
1545542122.739,,3.318086e+003,2.999997e+002,3.248139e-003,0.000000e+000,1.023489e-002,0.000000e+000,3,9.687459e-001,1.825000e+000,,,,,,,,,,,,,,,,,,0,4.000000e+000,1.000000e+000,5,1,0.000000e+000,0,0,0,
1545543934.006,,6.745316e+003,3.000038e+002,4.845242e-003,0.000000e+000,9.603905e-003,0.000000e+000,3,9.698830e-001,1.825000e+000,,,,,,,,,,,,,,,,,,0,4.000000e+000,1.000000e+000,5,1,8.300781e-003,0,1,0,
1545549088.367,,2.690407e+004,2.999956e+002,1.049250e-002,0.000000e+000,6.335700e-003,0.000000e+000,3,9.725013e-001,1.825000e+000,,,,,,,,,,,,,,,,,,0,4.000000e+000,1.000000e+000,5,1,8.209229e-003,0,1,0,
1545552447.866,,1.839599e+003,2.999997e+002,1.946005e-003,0.000000e+000,1.235131e-002,0.000000e+000,3,9.682541e-001,1.825000e+000,,,,,,,,,,,,,,,,,,0,4.000000e+000,1.000000e+000,5,1,0.000000e+000,0,0,0,
1545553969.526,,4.787828e+003,2.999956e+002,4.105037e-003,0.000000e+000,9.833829e-003,0.000000e+000,3,9.692264e-001,1.825000e+000,,,,,,,,,,,,,,,,,,0,4.000000e+000,1.000000e+000,5,1,8.209229e-003,0,0,0,
1545557045.057,,1.049882e+004,2.999997e+002,6.001345e-003,0.000000e+000,8.689574e-003,0.000000e+000,3,9.706067e-001,1.825000e+000,,,,,,,,,,,,,,,,,,0,4.000000e+000,1.000000e+000,5,1,0.000000e+000,0,0,0,
1545562880.883,,-8.268256e+002,2.999997e+002,9.781474e-005,0.000000e+000,1.099008e-001,0.000000e+000,3,9.635140e-001,1.825000e+000,,,,,,,,,,,,,,,,,,0,4.000000e+000,1.000000e+000,5,1,0.000000e+000,0,0,0,
1545564139.756,,3.318086e+003,2.999956e+002,3.106578e-003,0.000000e+000,1.025825e-002,0.000000e+000,3,9.690068e-001,1.825000e+000,,,,,,,,,,,,,,,,,,0,4.000000e+000,1.000000e+000,5,1,8.209229e-003,0,0,0,
1545565949.141,,6.745316e+003,2.999956e+002,4.828996e-003,0.000000e+000,9.988894e-003,0.000000e+000,3,9.697776e-001,1.825000e+000,,,,,,,,,,,,,,,,,,0,4.000000e+000,1.000000e+000,5,1,8.209229e-003,0,0,0,
1545571082.450,,2.690479e+004,3.000038e+002,1.049206e-002,0.000000e+000,7.167456e-003,0.000000e+000,3,9.724904e-001,1.825000e+000,,,,,,,,,,,,,,,,,,0,4.000000e+000,1.000000e+000,5,1,8.300781e-003,0,1,0,
1545574462.789,,1.839671e+003,2.999998e+002,1.762401e-003,0.000000e+000,1.343566e-002,0.000000e+000,3,9.682201e-001,1.825000e+000,,,,,,,,,,,,,,,,,,0,4.000000e+000,1.000000e+000,5,1,1.651001e-002,0,0,0,
1545575994.415,,4.787972e+003,2.999956e+002,4.061373e-003,0.000000e+000,1.070614e-002,0.000000e+000,3,9.692753e-001,1.825000e+000,,,,,,,,,,,,,,,,,,0,4.000000e+000,1.000000e+000,5,1,8.209229e-003,0,0,0,
1545579076.447,,1.049882e+004,2.999997e+002,5.995114e-003,0.000000e+000,9.904953e-003,0.000000e+000,3,9.705932e-001,1.825000e+000,,,,,,,,,,,,,,,,,,0,4.000000e+000,1.000000e+000,5,1,0.000000e+000,0,0,0,
1545584930.518,,-8.268401e+002,2.999997e+002,-9.845287e-005,0.000000e+000,-7.568919e-002,0.000000e+000,3,9.789119e-001,1.825000e+000,,,,,,,,,,,,,,,,,,0,4.000000e+000,1.000000e+000,5,1,0.000000e+000,0,0,0,
1545586195.607,,3.318159e+003,2.999997e+002,2.948657e-003,0.000000e+000,1.103890e-002,0.000000e+000,3,9.690219e-001,1.825000e+000,,,,,,,,,,,,,,,,,,0,4.000000e+000,1.000000e+000,5,1,0.000000e+000,0,0,0,
1545588000.912,,6.745606e+003,2.999997e+002,4.812064e-003,0.000000e+000,1.103062e-002,0.000000e+000,3,9.698466e-001,1.825000e+000,,,,,,,,,,,,,,,,,,0,4.000000e+000,1.000000e+000,5,1,0.000000e+000,0,0,0,
1545593146.618,,2.690551e+004,2.999956e+002,1.049365e-002,0.000000e+000,8.345127e-003,0.000000e+000,3,9.724674e-001,1.825000e+000,,,,,,,,,,,,,,,,,,0,4.000000e+000,1.000000e+000,5,1,8.209229e-003,0,1,0,
1545596589.848,,1.839743e+003,2.999997e+002,1.572730e-003,0.000000e+000,1.385891e-002,0.000000e+000,3,9.683115e-001,1.825000e+000,,,,,,,,,,,,,,,,,,0,4.000000e+000,1.000000e+000,5,1,0.000000e+000,0,0,0,
1545598125.177,,4.787972e+003,2.999998e+002,3.983242e-003,0.000000e+000,1.173745e-002,0.000000e+000,3,9.692441e-001,1.825000e+000,,,,,,,,,,,,,,,,,,0,4.000000e+000,1.000000e+000,5,1,1.651001e-002,0,0,0,
1545601221.085,,1.049911e+004,3.000038e+002,5.990129e-003,0.000000e+000,1.052545e-002,0.000000e+000,3,9.705953e-001,1.825000e+000,,,,,,,,,,,,,,,,,,0,4.000000e+000,1.000000e+000,5,1,8.300781e-003,0,1,0,
1545607091.254,,-8.267966e+002,2.999997e+002,-2.884553e-004,0.000000e+000,-1.523467e-002,0.000000e+000,3,9.705167e-001,1.825000e+000,,,,,,,,,,,,,,,,,,0,4.000000e+000,1.000000e+000,5,1,0.000000e+000,0,1,0,
1545608453.013,,3.318159e+003,2.999997e+002,2.789729e-003,0.000000e+000,1.070692e-002,0.000000e+000,3,9.690951e-001,1.825000e+000,,,,,,,,,,,,,,,,,,0,4.000000e+000,1.000000e+000,5,1,0.000000e+000,0,1,0,
1545610256.120,,6.745461e+003,2.999997e+002,4.792502e-003,0.000000e+000,1.046890e-002,0.000000e+000,3,9.698056e-001,1.825000e+000,,,,,,,,,,,,,,,,,,0,4.000000e+000,1.000000e+000,5,1,0.000000e+000,0,1,0,
1545615397.145,,2.690479e+004,2.999997e+002,1.049219e-002,0.000000e+000,6.957703e-003,0.000000e+000,3,9.725013e-001,1.825000e+000,,,,,,,,,,,,,,,,,,0,4.000000e+000,1.000000e+000,5,1,0.000000e+000,0,1,0,
1545619088.059,,1.839599e+003,2.999956e+002,1.382214e-003,0.000000e+000,1.136891e-002,0.000000e+000,3,9.688556e-001,1.825000e+000,,,,,,,,,,,,,,,,,,0,4.000000e+000,1.000000e+000,5,1,8.209229e-003,0,0,0,
1545620695.529,,4.787828e+003,2.999997e+002,3.871701e-003,0.000000e+000,9.265406e-003,0.000000e+000,3,9.693430e-001,1.825000e+000,,,,,,,,,,,,,,,,,,0,4.000000e+000,1.000000e+000,5,1,0.000000e+000,0,1,0,
1545623791.198,,1.049911e+004,3.000038e+002,5.982983e-003,0.000000e+000,8.113393e-003,0.000000e+000,3,9.705917e-001,1.825000e+000,,,,,,,,,,,,,,,,,,0,4.000000e+000,1.000000e+000,5,1,8.300781e-003,0,1,0,
1545629757.538,,-1.353747e+003,2.999997e+002,-7.352890e-004,0.000000e+000,-1.032115e-003,0.000000e+000,3,9.696845e-001,1.825000e+000,,,,,,,,,,,,,,,,,,0,4.000000e+000,1.000000e+000,5,1,0.000000e+000,0,0,0,
1545631193.927,,3.178514e+003,2.999998e+002,2.482832e-003,0.000000e+000,7.721988e-003,0.000000e+000,3,9.691545e-001,1.825000e+000,,,,,,,,,,,,,,,,,,0,4.000000e+000,1.000000e+000,5,1,1.651001e-002,0,0,0,
1545632951.277,,6.501299e+003,2.999997e+002,4.677065e-003,0.000000e+000,7.888100e-003,0.000000e+000,3,9.698413e-001,1.825000e+000,,,,,,,,,,,,,,,,,,0,4.000000e+000,1.000000e+000,5,1,0.000000e+000,0,0,0,
1545637798.171,,2.337898e+004,2.999956e+002,9.551106e-003,0.000000e+000,4.981825e-003,0.000000e+000,3,9.722728e-001,1.825000e+000,,,,,,,,,,,,,,,,,,0,4.000000e+000,1.000000e+000,5,1,8.209229e-003,0,1,0,
1545641718.892,,1.492206e+003,2.999997e+002,8.791889e-004,0.000000e+000,1.115112e-002,0.000000e+000,3,9.691383e-001,1.825000e+000,,,,,,,,,,,,,,,,,,0,4.000000e+000,1.000000e+000,5,1,0.000000e+000,0,1,0,
1545643366.494,,4.470520e+003,2.999997e+002,3.501619e-003,0.000000e+000,7.586744e-003,0.000000e+000,3,9.695163e-001,1.825000e+000,,,,,,,,,,,,,,,,,,0,4.000000e+000,1.000000e+000,5,1,0.000000e+000,0,1,0,
1545646180.783,,9.433121e+003,2.999997e+002,5.649894e-003,0.000000e+000,7.620015e-003,0.000000e+000,3,9.704033e-001,1.825000e+000,,,,,,,,,,,,,,,,,,0,4.000000e+000,1.000000e+000,5,1,0.000000e+000,0,1,0,
1545652427.199,,-2.852242e+003,2.999956e+002,-1.544403e-003,0.000000e+000,3.859294e-003,0.000000e+000,3,9.704230e-001,1.825000e+000,,,,,,,,,,,,,,,,,,0,4.000000e+000,1.000000e+000,5,1,8.209229e-003,0,1,0,
1545653872.468,,2.898429e+003,3.000038e+002,2.042453e-003,0.000000e+000,7.480414e-003,0.000000e+000,3,9.693348e-001,1.825000e+000,,,,,,,,,,,,,,,,,,0,4.000000e+000,1.000000e+000,5,1,8.300781e-003,0,1,0,
1545655602.178,,6.057500e+003,2.999997e+002,4.464057e-003,0.000000e+000,8.631952e-003,0.000000e+000,3,9.697605e-001,1.825000e+000,,,,,,,,,,,,,,,,,,0,4.000000e+000,1.000000e+000,5,1,0.000000e+000,0,0,0,
1545659933.028,,1.830853e+004,2.999997e+002,8.182256e-003,0.000000e+000,6.629750e-003,0.000000e+000,3,9.718212e-001,1.825000e+000,,,,,,,,,,,,,,,,,,0,4.000000e+000,1.000000e+000,5,1,0.000000e+000,0,0,0,
1545664360.370,,1.084808e+003,2.999915e+002,3.537014e-004,0.000000e+000,1.588287e-002,0.000000e+000,3,9.696972e-001,1.825000e+000,,,,,,,,,,,,,,,,,,0,4.000000e+000,1.000000e+000,5,1,0.000000e+000,0,0,0,
1545666084.890,,4.171497e+003,2.999997e+002,3.107952e-003,0.000000e+000,8.758014e-003,0.000000e+000,3,9.695848e-001,1.825000e+000,,,,,,,,,,,,,,,,,,0,4.000000e+000,1.000000e+000,5,1,0.000000e+000,0,1,0,
1545668611.787,,8.573566e+003,2.999997e+002,5.366705e-003,0.000000e+000,8.877436e-003,0.000000e+000,3,9.702043e-001,1.825000e+000,,,,,,,,,,,,,,,,,,0,4.000000e+000,1.000000e+000,5,1,0.000000e+000,0,1,0,
1545675079.650,,-5.359274e+003,2.999997e+002,-2.677308e-003,0.000000e+000,6.667284e-003,0.000000e+000,3,9.710207e-001,1.825000e+000,,,,,,,,,,,,,,,,,,0,4.000000e+000,1.000000e+000,5,1,0.000000e+000,0,1,0,
1545676568.247,,2.614513e+003,2.999997e+002,1.589413e-003,0.000000e+000,8.180453e-003,0.000000e+000,3,9.696439e-001,1.825000e+000,,,,,,,,,,,,,,,,,,0,4.000000e+000,1.000000e+000,5,1,0.000000e+000,0,1,0,
1545678353.260,,5.662272e+003,2.999956e+002,4.147953e-003,0.000000e+000,9.673664e-003,0.000000e+000,3,9.695698e-001,1.825000e+000,,,,,,,,,,,,,,,,,,0,4.000000e+000,1.000000e+000,5,1,8.209229e-003,0,0,0,
1545682257.860,,1.500071e+004,2.999997e+002,7.266497e-003,0.000000e+000,8.529929e-003,0.000000e+000,3,9.713225e-001,1.825000e+000,,,,,,,,,,,,,,,,,,0,4.000000e+000,1.000000e+000,5,1,0.000000e+000,0,1,0,
1545687142.099,,6.030612e+002,2.999997e+002,-1.926684e-004,0.000000e+000,-1.446821e-003,0.000000e+000,3,9.537479e-001,1.825000e+000,,,,,,,,,,,,,,,,,,0,4.000000e+000,1.000000e+000,5,1,0.000000e+000,0,0,0,
1545688777.822,,3.880281e+003,2.999997e+002,2.687725e-003,0.000000e+000,8.283189e-003,0.000000e+000,3,9.695281e-001,1.825000e+000,,,,,,,,,,,,,,,,,,0,4.000000e+000,1.000000e+000,5,1,0.000000e+000,0,1,0,
1545691054.280,,7.872595e+003,2.999956e+002,5.112233e-003,0.000000e+000,9.455544e-003,0.000000e+000,3,9.700388e-001,1.825000e+000,,,,,,,,,,,,,,,,,,0,4.000000e+000,1.000000e+000,5,1,8.209229e-003,0,0,0,
1545697467.498,,5.038207e+004,2.999956e+002,1.661022e-002,0.000000e+000,4.320955e-003,0.000000e+000,3,9.735023e-001,1.825000e+000,,,,,,,,,,,,,,,,,,0,4.000000e+000,1.000000e+000,5,1,8.209229e-003,0,1,0,
1545699173.458,,2.317369e+003,2.999997e+002,1.116872e-003,0.000000e+000,5.563648e-003,0.000000e+000,3,9.701496e-001,1.825000e+000,,,,,,,,,,,,,,,,,,0,4.000000e+000,1.000000e+000,5,1,0.000000e+000,0,1,0,
1545701011.312,,5.294801e+003,2.999997e+002,3.768678e-003,0.000000e+000,7.887357e-003,0.000000e+000,3,9.698285e-001,1.825000e+000,,,,,,,,,,,,,,,,,,0,4.000000e+000,1.000000e+000,5,1,0.000000e+000,0,1,0,
1545704581.149,,1.275279e+004,2.999997e+002,6.622250e-003,0.000000e+000,6.775499e-003,0.000000e+000,3,9.710674e-001,1.825000e+000,,,,,,,,,,,,,,,,,,0,4.000000e+000,1.000000e+000,5,1,0.000000e+000,0,0,0,
1545710109.734,,-3.811615e+002,2.999998e+002,-9.880193e-004,0.000000e+000,5.454977e-003,0.000000e+000,3,9.675846e-001,1.825000e+000,,,,,,,,,,,,,,,,,,0,4.000000e+000,1.000000e+000,5,1,1.651001e-002,0,1,0,
1545711499.524,,3.456575e+003,2.999997e+002,2.098342e-003,0.000000e+000,4.706868e-003,0.000000e+000,3,9.700015e-001,1.825000e+000,,,,,,,,,,,,,,,,,,0,4.000000e+000,1.000000e+000,5,1,0.000000e+000,0,1,0,
1545713617.564,,6.995839e+003,3.000038e+002,4.744625e-003,0.000000e+000,6.981294e-003,0.000000e+000,3,9.697835e-001,1.825000e+000,,,,,,,,,,,,,,,,,,0,4.000000e+000,1.000000e+000,5,1,8.300781e-003,0,1,0,
1545719023.779,,3.127051e+004,2.999997e+002,1.163656e-002,0.000000e+000,2.941029e-003,0.000000e+000,3,9.728456e-001,1.825000e+000,,,,,,,,,,,,,,,,,,0,4.000000e+000,1.000000e+000,5,1,0.000000e+000,0,1,0,
1545722338.388,,1.667962e+003,2.999956e+002,3.277435e-004,0.000000e+000,-1.669222e-003,0.000000e+000,3,9.735273e-001,1.825000e+000,,,,,,,,,,,,,,,,,,0,4.000000e+000,1.000000e+000,5,1,8.209229e-003,0,1,0,
1545724095.748,,4.625921e+003,2.999998e+002,3.083643e-003,0.000000e+000,4.613949e-003,0.000000e+000,3,9.700440e-001,1.825000e+000,,,,,,,,,,,,,,,,,,0,4.000000e+000,1.000000e+000,5,1,1.651001e-002,0,1,0,
1545727033.495,,9.936194e+003,2.999997e+002,5.768177e-003,0.000000e+000,5.610179e-003,0.000000e+000,3,9.705485e-001,1.825000e+000,,,,,,,,,,,,,,,,,,0,4.000000e+000,1.000000e+000,5,1,0.000000e+000,0,1,0,
1545733335.077,,-2.852242e+003,2.999956e+002,-2.206889e-003,0.000000e+000,5.384719e-003,0.000000e+000,3,9.694123e-001,1.825000e+000,,,,,,,,,,,,,,,,,,0,4.000000e+000,1.000000e+000,5,1,8.209229e-003,0,1,0,
1545734625.940,,2.898357e+003,2.999997e+002,1.381884e-003,0.000000e+000,1.846285e-003,0.000000e+000,3,9.705954e-001,1.825000e+000,,,,,,,,,,,,,,,,,,0,4.000000e+000,1.000000e+000,5,1,0.000000e+000,0,1,0,
1545736617.875,,6.057500e+003,3.000038e+002,4.086447e-003,0.000000e+000,6.040666e-003,0.000000e+000,3,9.700220e-001,1.825000e+000,,,,,,,,,,,,,,,,,,0,4.000000e+000,1.000000e+000,5,1,8.300781e-003,0,1,0,
1545740940.578,,1.830853e+004,2.999997e+002,8.172011e-003,0.000000e+000,4.830234e-003,0.000000e+000,3,9.718598e-001,1.825000e+000,,,,,,,,,,,,,,,,,,0,4.000000e+000,1.000000e+000,5,1,0.000000e+000,0,1,0,
1545745492.499,,8.529043e+002,3.000038e+002,-5.135030e-004,0.000000e+000,9.180639e-003,0.000000e+000,3,9.634320e-001,1.825000e+000,,,,,,,,,,,,,,,,,,0,4.000000e+000,1.000000e+000,5,1,8.300781e-003,0,1,0,
1545747083.488,,4.022889e+003,3.000038e+002,2.381541e-003,0.000000e+000,4.566176e-003,0.000000e+000,3,9.702525e-001,1.825000e+000,,,,,,,,,,,,,,,,,,0,4.000000e+000,1.000000e+000,5,1,8.300781e-003,0,1,0,
1545749697.051,,8.210289e+003,2.999997e+002,5.170350e-003,0.000000e+000,7.079440e-003,0.000000e+000,3,9.702206e-001,1.825000e+000,,,,,,,,,,,,,,,,,,0,4.000000e+000,1.000000e+000,5,1,0.000000e+000,0,1,0,
1545756262.781,,-8.210722e+003,2.999956e+002,-4.216278e-003,0.000000e+000,5.998420e-003,0.000000e+000,3,9.710541e-001,1.825000e+000,,,,,,,,,,,,,,,,,,0,4.000000e+000,1.000000e+000,5,1,8.209229e-003,0,1,0,
1545757851.312,,2.317442e+003,2.999997e+002,6.255627e-004,0.000000e+000,-2.281298e-003,0.000000e+000,3,9.724900e-001,1.825000e+000,,,,,,,,,,,,,,,,,,0,4.000000e+000,1.000000e+000,5,1,0.000000e+000,0,0,0,
1545759826.374,,5.294801e+003,2.999956e+002,3.399546e-003,0.000000e+000,6.514422e-003,0.000000e+000,3,9.700689e-001,1.825000e+000,,,,,,,,,,,,,,,,,,0,4.000000e+000,1.000000e+000,5,1,8.209229e-003,0,1,0,
1545763410.522,,1.275337e+004,3.000038e+002,6.606612e-003,0.000000e+000,7.163124e-003,0.000000e+000,3,9.710262e-001,1.825000e+000,,,,,,,,,,,,,,,,,,0,4.000000e+000,1.000000e+000,5,1,8.300781e-003,0,1,0,
1545768950.397,,-3.811760e+002,2.999956e+002,-1.447664e-003,0.000000e+000,9.376694e-003,0.000000e+000,3,9.674168e-001,1.825000e+000,,,,,,,,,,,,,,,,,,0,4.000000e+000,1.000000e+000,5,1,8.209229e-003,0,1,0,
1545770341.238,,3.456647e+003,2.999956e+002,1.659491e-003,0.000000e+000,3.429445e-003,0.000000e+000,3,9.708056e-001,1.825000e+000,,,,,,,,,,,,,,,,,,0,4.000000e+000,1.000000e+000,5,1,8.209229e-003,0,1,0,
1545772677.162,,6.995984e+003,2.999997e+002,4.473786e-003,0.000000e+000,8.099392e-003,0.000000e+000,3,9.700592e-001,1.825000e+000,,,,,,,,,,,,,,,,,,0,4.000000e+000,1.000000e+000,5,1,0.000000e+000,0,0,0,
1545778095.119,,3.127123e+004,2.999997e+002,1.163488e-002,0.000000e+000,4.725895e-003,0.000000e+000,3,9.727876e-001,1.825000e+000,,,,,,,,,,,,,,,,,,0,4.000000e+000,1.000000e+000,5,1,0.000000e+000,0,1,0,
1545781540.618,,1.492236e+003,3.000038e+002,-3.150979e-004,0.000000e+000,2.464600e-002,0.000000e+000,3,9.607697e-001,1.825000e+000,,,,,,,,,,,,,,,,,,0,4.000000e+000,1.000000e+000,5,1,8.300781e-003,0,1,0,
1545783363.763,,4.470520e+003,2.999997e+002,2.526426e-003,0.000000e+000,4.665534e-003,0.000000e+000,3,9.702361e-001,1.825000e+000,,,,,,,,,,,,,,,,,,0,4.000000e+000,1.000000e+000,5,1,0.000000e+000,0,0,0,
1545786641.390,,9.433410e+003,2.999956e+002,5.563001e-003,0.000000e+000,6.549578e-003,0.000000e+000,3,9.705508e-001,1.825000e+000,,,,,,,,,,,,,,,,,,0,4.000000e+000,1.000000e+000,5,1,8.209229e-003,0,0,0,
1545793397.106,,-5.358985e+003,2.999997e+002,-3.550565e-003,0.000000e+000,5.841412e-003,0.000000e+000,3,9.700588e-001,1.825000e+000,,,,,,,,,,,,,,,,,,0,4.000000e+000,1.000000e+000,5,1,0.000000e+000,0,1,0,
1545794786.087,,2.614441e+003,2.999998e+002,6.205312e-004,0.000000e+000,-7.448939e-003,0.000000e+000,3,9.729055e-001,1.825000e+000,,,,,,,,,,,,,,,,,,0,4.000000e+000,1.000000e+000,5,1,1.651001e-002,0,1,0,
1545796782.314,,5.661838e+003,3.000038e+002,3.445054e-003,0.000000e+000,4.427487e-003,0.000000e+000,3,9.702760e-001,1.825000e+000,,,,,,,,,,,,,,,,,,0,4.000000e+000,1.000000e+000,5,1,8.300781e-003,0,1,0,
1545800788.094,,1.500013e+004,2.999915e+002,7.243703e-003,0.000000e+000,4.097665e-003,0.000000e+000,3,9.714653e-001,1.825000e+000,,,,,,,,,,,,,,,,,,0,4.000000e+000,1.000000e+000,5,1,0.000000e+000,0,0,0,
1545806066.105,,4.770482e+000,2.999997e+002,-1.544685e-003,0.000000e+000,6.993098e-003,0.000000e+000,3,9.671682e-001,1.825000e+000,,,,,,,,,,,,,,,,,,0,4.000000e+000,1.000000e+000,5,1,0.000000e+000,0,1,0,
1545807481.418,,3.597015e+003,2.999956e+002,1.515324e-003,0.000000e+000,-1.920264e-003,0.000000e+000,3,9.713172e-001,1.825000e+000,,,,,,,,,,,,,,,,,,0,4.000000e+000,1.000000e+000,5,1,8.209229e-003,0,0,0,
1545809950.401,,7.270503e+003,2.999997e+002,4.439568e-003,0.000000e+000,4.362861e-003,0.000000e+000,3,9.704298e-001,1.825000e+000,,,,,,,,,,,,,,,,,,0,4.000000e+000,1.000000e+000,5,1,0.000000e+000,0,1,0,
1545815705.394,,3.657947e+004,2.999997e+002,1.301968e-002,0.000000e+000,1.371792e-003,0.000000e+000,3,9.730998e-001,1.825000e+000,,,,,,,,,,,,,,,,,,0,4.000000e+000,1.000000e+000,5,1,0.000000e+000,0,1,0,
1545818721.378,,1.667992e+003,2.999915e+002,-4.362491e-004,0.000000e+000,2.190372e-002,0.000000e+000,3,9.615185e-001,1.825000e+000,,,,,,,,,,,,,,,,,,0,4.000000e+000,1.000000e+000,5,1,0.000000e+000,0,1,0,
1545820450.048,,4.625921e+003,2.999997e+002,2.422500e-003,0.000000e+000,1.831653e-003,0.000000e+000,3,9.706824e-001,1.825000e+000,,,,,,,,,,,,,,,,,,0,4.000000e+000,1.000000e+000,5,1,0.000000e+000,0,1,0,
1545823803.219,,9.935900e+003,2.999997e+002,5.659555e-003,0.000000e+000,4.914524e-003,0.000000e+000,3,9.706218e-001,1.825000e+000,,,,,,,,,,,,,,,,,,0,4.000000e+000,1.000000e+000,5,1,0.000000e+000,0,1,0,
1545830260.621,,-3.994628e+003,2.999956e+002,-3.329862e-003,0.000000e+000,6.182378e-003,0.000000e+000,3,9.693503e-001,1.825000e+000,,,,,,,,,,,,,,,,,,0,4.000000e+000,1.000000e+000,5,1,8.209229e-003,0,1,0,
1545831536.464,,2.756905e+003,3.000038e+002,4.942683e-004,0.000000e+000,-1.503414e-002,0.000000e+000,3,9.759567e-001,1.825000e+000,,,,,,,,,,,,,,,,,,0,4.000000e+000,1.000000e+000,5,1,8.300781e-003,0,1,0,
1545833574.617,,5.858730e+003,2.999956e+002,3.367599e-003,0.000000e+000,4.180380e-003,0.000000e+000,3,9.706330e-001,1.825000e+000,,,,,,,,,,,,,,,,,,0,4.000000e+000,1.000000e+000,5,1,8.209229e-003,0,0,0,
1545837905.515,,1.648794e+004,2.999997e+002,7.654774e-003,0.000000e+000,4.567804e-003,0.000000e+000,3,9.716405e-001,1.825000e+000,,,,,,,,,,,,,,,,,,0,4.000000e+000,1.000000e+000,5,1,0.000000e+000,0,0,0,
1545843182.910,,4.770482e+000,2.999997e+002,-1.808410e-003,0.000000e+000,9.005996e-003,0.000000e+000,3,9.671456e-001,1.825000e+000,,,,,,,,,,,,,,,,,,0,4.000000e+000,1.000000e+000,5,1,0.000000e+000,0,1,0,
1545844619.164,,3.597088e+003,2.999997e+002,1.249606e-003,0.000000e+000,-1.902480e-003,0.000000e+000,3,9.722257e-001,1.825000e+000,,,,,,,,,,,,,,,,,,0,4.000000e+000,1.000000e+000,5,1,0.000000e+000,0,1,0,
1545847020.988,,7.270358e+003,2.999956e+002,4.233630e-003,0.000000e+000,5.810577e-003,0.000000e+000,3,9.706303e-001,1.825000e+000,,,,,,,,,,,,,,,,,,0,4.000000e+000,1.000000e+000,5,1,8.209229e-003,0,0,0,
1545853027.602,,3.658020e+004,2.999915e+002,1.301702e-002,0.000000e+000,3.442617e-003,0.000000e+000,3,9.730917e-001,1.825000e+000,,,,,,,,,,,,,,,,,,0,4.000000e+000,1.000000e+000,5,1,0.000000e+000,0,0,0,
1545856267.204,,1.492264e+003,2.999997e+002,-8.501711e-004,0.000000e+000,1.801565e-002,0.000000e+000,3,9.651985e-001,1.825000e+000,,,,,,,,,,,,,,,,,,0,4.000000e+000,1.000000e+000,5,1,0.000000e+000,0,1,0,
1545857827.153,,4.470520e+003,2.999997e+002,2.031258e-003,0.000000e+000,2.452483e-003,0.000000e+000,3,9.713882e-001,1.825000e+000,,,,,,,,,,,,,,,,,,0,4.000000e+000,1.000000e+000,5,1,0.000000e+000,0,1,0,
1545861111.363,,9.433699e+003,3.000038e+002,5.288980e-003,0.000000e+000,6.399953e-003,0.000000e+000,3,9.707631e-001,1.825000e+000,,,,,,,,,,,,,,,,,,0,4.000000e+000,1.000000e+000,5,1,8.300781e-003,0,1,0,
1545867978.188,,-6.949435e+003,2.999956e+002,-4.539781e-003,0.000000e+000,6.341053e-003,0.000000e+000,3,9.701126e-001,1.825000e+000,,,,,,,,,,,,,,,,,,0,4.000000e+000,1.000000e+000,5,1,8.209229e-003,0,0,0,
1545869321.014,,2.469954e+003,2.999956e+002,-4.606170e-005,0.000000e+000,2.846830e-001,0.000000e+000,3,8.981346e-001,1.825000e+000,,,,,,,,,,,,,,,,,,0,4.000000e+000,1.000000e+000,5,1,8.209229e-003,0,0,0,
1545871165.858,,5.472175e+003,2.999956e+002,2.839378e-003,0.000000e+000,3.407079e-003,0.000000e+000,3,9.708217e-001,1.825000e+000,,,,,,,,,,,,,,,,,,0,4.000000e+000,1.000000e+000,5,1,8.209229e-003,0,1,0,
1545875361.107,,1.377484e+004,3.000038e+002,6.861196e-003,0.000000e+000,4.621961e-003,0.000000e+000,3,9.713094e-001,1.825000e+000,,,,,,,,,,,,,,,,,,0,4.000000e+000,1.000000e+000,5,1,8.300781e-003,0,0,0,
1545881379.032,,-1.353776e+003,3.000038e+002,-2.664729e-003,0.000000e+000,7.230363e-003,0.000000e+000,3,9.678328e-001,1.825000e+000,,,,,,,,,,,,,,,,,,0,4.000000e+000,1.000000e+000,5,1,8.300781e-003,0,1,0,
1545882701.524,,3.178514e+003,2.999956e+002,5.834721e-004,0.000000e+000,-1.617039e-002,0.000000e+000,3,9.765518e-001,1.825000e+000,,,,,,,,,,,,,,,,,,0,4.000000e+000,1.000000e+000,5,1,8.209229e-003,0,1,0,
1545884738.684,,6.501154e+003,2.999997e+002,3.542429e-003,0.000000e+000,3.114476e-003,0.000000e+000,3,9.708350e-001,1.825000e+000,,,,,,,,,,,,,,,,,,0,4.000000e+000,1.000000e+000,5,1,0.000000e+000,0,1,0,
1545889966.558,,2.337825e+004,2.999997e+002,9.530211e-003,0.000000e+000,1.977972e-003,0.000000e+000,3,9.723621e-001,1.825000e+000,,,,,,,,,,,,,,,,,,0,4.000000e+000,1.000000e+000,5,1,0.000000e+000,0,1,0,
1545894633.644,,6.030612e+002,2.999956e+002,-1.737866e-003,0.000000e+000,8.040747e-003,0.000000e+000,3,9.662212e-001,1.825000e+000,,,,,,,,,,,,,,,,,,0,4.000000e+000,1.000000e+000,5,1,8.209229e-003,0,1,0,
1545896078.697,,3.880136e+003,3.000038e+002,1.228511e-003,0.000000e+000,-5.060082e-003,0.000000e+000,3,9.732287e-001,1.825000e+000,,,,,,,,,,,,,,,,,,0,4.000000e+000,1.000000e+000,5,1,8.300781e-003,0,0,0,
1545898723.698,,7.872885e+003,2.999956e+002,4.336248e-003,0.000000e+000,3.056847e-003,0.000000e+000,3,9.707962e-001,1.825000e+000,,,,,,,,,,,,,,,,,,0,4.000000e+000,1.000000e+000,5,1,8.209229e-003,0,1,0,
1545905383.412,,5.037773e+004,2.999956e+002,1.659559e-002,0.000000e+000,1.461806e-004,0.000000e+000,3,9.735940e-001,1.825000e+000,,,,,,,,,,,,,,,,,,0,4.000000e+000,1.000000e+000,5,1,8.209229e-003,0,0,0,
1545907898.336,,1.667992e+003,3.000038e+002,-9.991231e-004,0.000000e+000,1.432534e-002,0.000000e+000,3,9.646736e-001,1.825000e+000,,,,,,,,,,,,,,,,,,0,4.000000e+000,1.000000e+000,5,1,8.300781e-003,0,1,0,
1545909528.571,,4.625921e+003,2.999997e+002,1.898271e-003,0.000000e+000,-1.684522e-003,0.000000e+000,3,9.721646e-001,1.825000e+000,,,,,,,,,,,,,,,,,,0,4.000000e+000,1.000000e+000,5,1,0.000000e+000,0,1,0,
1545912965.766,,9.935900e+003,2.999997e+002,5.302268e-003,0.000000e+000,3.797028e-003,0.000000e+000,3,9.709485e-001,1.825000e+000,,,,,,,,,,,,,,,,,,0,4.000000e+000,1.000000e+000,5,1,0.000000e+000,0,0,0,
1545920080.274,,-8.961854e+003,2.999997e+002,-5.400207e-003,0.000000e+000,4.491725e-003,0.000000e+000,3,9.705208e-001,1.825000e+000,,,,,,,,,,,,,,,,,,0,4.000000e+000,1.000000e+000,5,1,0.000000e+000,0,1,0,
1545921537.857,,2.317369e+003,3.000038e+002,-4.717324e-004,0.000000e+000,3.162769e-002,0.000000e+000,3,9.588864e-001,1.825000e+000,,,,,,,,,,,,,,,,,,0,4.000000e+000,1.000000e+000,5,1,8.300781e-003,0,1,0,
1545923222.447,,5.294657e+003,2.999997e+002,2.439971e-003,0.000000e+000,1.663764e-003,0.000000e+000,3,9.714226e-001,1.825000e+000,,,,,,,,,,,,,,,,,,0,4.000000e+000,1.000000e+000,5,1,0.000000e+000,0,1,0,
1545927259.276,,1.275337e+004,2.999997e+002,6.357009e-003,0.000000e+000,4.249710e-003,0.000000e+000,3,9.713361e-001,1.825000e+000,,,,,,,,,,,,,,,,,,0,4.000000e+000,1.000000e+000,5,1,0.000000e+000,0,1,0,
1545933864.141,,-2.852242e+003,2.999997e+002,-3.477581e-003,0.000000e+000,7.398209e-003,0.000000e+000,3,9.685533e-001,1.825000e+000,,,,,,,,,,,,,,,,,,0,4.000000e+000,1.000000e+000,5,1,0.000000e+000,0,1,0,
1545935130.381,,2.898357e+003,2.999997e+002,6.842767e-005,0.000000e+000,-1.746189e-001,0.000000e+000,3,9.188569e-001,1.825000e+000,,,,,,,,,,,,,,,,,,0,4.000000e+000,1.000000e+000,5,1,0.000000e+000,0,1,0,
1545937060.147,,6.057500e+003,2.999997e+002,3.009280e-003,0.000000e+000,3.499012e-003,0.000000e+000,3,9.711834e-001,1.825000e+000,,,,,,,,,,,,,,,,,,0,4.000000e+000,1.000000e+000,5,1,0.000000e+000,0,0,0,
1545941845.065,,1.830853e+004,2.999997e+002,8.090098e-003,0.000000e+000,4.269087e-003,0.000000e+000,3,9.718709e-001,1.825000e+000,,,,,,,,,,,,,,,,,,0,4.000000e+000,1.000000e+000,5,1,0.000000e+000,0,1,0,
1545947830.741,,-8.268401e+002,2.999997e+002,-2.716532e-003,0.000000e+000,8.508290e-003,0.000000e+000,3,9.674872e-001,1.825000e+000,,,,,,,,,,,,,,,,,,0,4.000000e+000,1.000000e+000,5,1,0.000000e+000,0,1,0,
1545949200.983,,3.318014e+003,2.999997e+002,4.488929e-004,0.000000e+000,-2.158674e-002,0.000000e+000,3,9.789156e-001,1.825000e+000,,,,,,,,,,,,,,,,,,0,4.000000e+000,1.000000e+000,5,1,0.000000e+000,0,1,0,
1545951256.058,,6.745171e+003,2.999997e+002,3.464077e-003,0.000000e+000,4.198013e-003,0.000000e+000,3,9.710492e-001,1.825000e+000,,,,,,,,,,,,,,,,,,0,4.000000e+000,1.000000e+000,5,1,0.000000e+000,0,1,0,
1545956754.752,,2.690407e+004,2.999956e+002,1.046836e-002,0.000000e+000,2.527173e-003,0.000000e+000,3,9.726370e-001,1.825000e+000,,,,,,,,,,,,,,,,,,0,4.000000e+000,1.000000e+000,5,1,8.209229e-003,0,1,0,
1545962208.792,,4.784937e+000,2.999956e+002,-2.359340e-003,0.000000e+000,7.667099e-003,0.000000e+000,3,9.671811e-001,1.825000e+000,,,,,,,,,,,,,,,,,,0,4.000000e+000,1.000000e+000,5,1,8.209229e-003,0,1,0,
1545963621.514,,3.597015e+003,3.000038e+002,6.989055e-004,0.000000e+000,-1.352323e-002,0.000000e+000,3,9.755439e-001,1.825000e+000,,,,,,,,,,,,,,,,,,0,4.000000e+000,1.000000e+000,5,1,8.300781e-003,0,1,0,
1545965971.664,,7.270069e+003,2.999956e+002,3.775026e-003,0.000000e+000,3.017140e-003,0.000000e+000,3,9.710411e-001,1.825000e+000,,,,,,,,,,,,,,,,,,0,4.000000e+000,1.000000e+000,5,1,8.209229e-003,0,1,0,
1545971967.246,,3.657947e+004,2.999997e+002,1.301480e-002,0.000000e+000,3.322063e-004,0.000000e+000,3,9.732057e-001,1.825000e+000,,,,,,,,,,,,,,,,,,0,4.000000e+000,1.000000e+000,5,1,0.000000e+000,0,1,0,
1545977109.487,,3.159794e+002,2.999997e+002,-2.199310e-003,0.000000e+000,6.431655e-003,0.000000e+000,3,9.663259e-001,1.825000e+000,,,,,,,,,,,,,,,,,,0,4.000000e+000,1.000000e+000,5,1,0.000000e+000,0,1,0,
1545978537.161,,3.738540e+003,3.000038e+002,8.192094e-004,0.000000e+000,-1.182363e-002,0.000000e+000,3,9.746647e-001,1.825000e+000,,,,,,,,,,,,,,,,,,0,4.000000e+000,1.000000e+000,5,1,8.300781e-003,0,0,0,
1545980979.880,,7.554998e+003,2.999997e+002,3.929880e-003,0.000000e+000,2.036957e-003,0.000000e+000,3,9.710752e-001,1.825000e+000,,,,,,,,,,,,,,,,,,0,4.000000e+000,1.000000e+000,5,1,0.000000e+000,0,1,0,
1545987284.650,,4.288953e+004,2.999956e+002,1.465560e-002,0.000000e+000,-5.268065e-004,0.000000e+000,3,9.734507e-001,1.825000e+000,,,,,,,,,,,,,,,,,,0,4.000000e+000,1.000000e+000,5,1,8.209229e-003,0,1,0,
1545992497.436,,3.160083e+002,2.999997e+002,-2.216519e-003,0.000000e+000,7.232144e-003,0.000000e+000,3,9.667819e-001,1.825000e+000,,,,,,,,,,,,,,,,,,0,4.000000e+000,1.000000e+000,5,1,0.000000e+000,0,1,0,
1545993938.375,,3.738540e+003,3.000038e+002,8.058454e-004,0.000000e+000,-1.197524e-002,0.000000e+000,3,9.760268e-001,1.825000e+000,,,,,,,,,,,,,,,,,,0,4.000000e+000,1.000000e+000,5,1,8.300781e-003,0,1,0,
1545996368.337,,7.554853e+003,2.999956e+002,3.914942e-003,0.000000e+000,2.431187e-003,0.000000e+000,3,9.710968e-001,1.825000e+000,,,,,,,,,,,,,,,,,,0,4.000000e+000,1.000000e+000,5,1,8.209229e-003,0,1,0,
1546002677.359,,4.288953e+004,2.999956e+002,1.465611e-002,0.000000e+000,1.643114e-004,0.000000e+000,3,9.733741e-001,1.825000e+000,,,,,,,,,,,,,,,,,,0,4.000000e+000,1.000000e+000,5,1,8.209229e-003,0,1,0,
1546007971.924,,3.160083e+002,2.999997e+002,-2.230920e-003,0.000000e+000,7.657859e-003,0.000000e+000,3,9.664550e-001,1.825000e+000,,,,,,,,,,,,,,,,,,0,4.000000e+000,1.000000e+000,5,1,0.000000e+000,0,0,0,
1546009406.166,,3.738540e+003,2.999915e+002,7.897182e-004,0.000000e+000,-1.194966e-002,0.000000e+000,3,9.759130e-001,1.825000e+000,,,,,,,,,,,,,,,,,,0,4.000000e+000,1.000000e+000,5,1,0.000000e+000,0,0,0,
1546011838.254,,7.554998e+003,2.999997e+002,3.904359e-003,0.000000e+000,3.193721e-003,0.000000e+000,3,9.710804e-001,1.825000e+000,,,,,,,,,,,,,,,,,,0,4.000000e+000,1.000000e+000,5,1,0.000000e+000,0,1,0,
1546018143.284,,4.289096e+004,2.999956e+002,1.465405e-002,0.000000e+000,1.090355e-003,0.000000e+000,3,9.733509e-001,1.825000e+000,,,,,,,,,,,,,,,,,,0,4.000000e+000,1.000000e+000,5,1,8.209229e-003,0,0,0,
1546019057.316,,2.746641e-001,2.999956e+002,2.449501e-003,0.000000e+000,7.495960e-003,0.000000e+000,3,9.671114e-001,1.825000e+000,,,,,,,,,,,,,,,,,,0,4.000000e+000,1.000000e+000,5,1,8.209229e-003,0,1,0,